Workbook
Name DT_KR: [2]DT_KR!$B$4:$V$1168
Name Judul_Absensi_Karyawan: [3]Januari!$B$1
Name Judul1: [3]!Januari[[#Headers],[Nama Karyawan]]
Name Judul10: [3]!Oktober[[#Headers],[Nama Karyawan]]
Name Judul11: [3]!November[[#Headers],[Nama Karyawan]]
Name Judul12: [3]!Desember[[#Headers],[Nama Karyawan]]
Name Judul2: [3]!Februari[[#Headers],[Nama Karyawan]]
Name Judul3: [3]!Maret[[#Headers],[Nama Karyawan]]
Name Judul4: [3]!April[[#Headers],[Nama Karyawan]]
Name Judul5: [3]!Mei[[#Headers],[Nama Karyawan]]
Name Judul6: [3]!Juni[[#Headers],[Nama Karyawan]]
Name Judul7: [3]!Juli[[#Headers],[Nama Karyawan]]
Name Judul8: [3]!Agustus[[#Headers],[Nama Karyawan]]
Name Judul9: [3]!September[[#Headers],[Nama Karyawan]]
Name JudulKolom13: #REF!
Name JudulKolom13: #REF!
Name JudulKolom13: #REF!
Name JudulKolom13: #REF!
Name JudulKolom13: #REF!
Name JudulKolom13: #REF!
Name JudulKolom13: #REF!
Name JudulKolom13: #REF!
Name JudulKolom13: #REF!
Name Kustomkunci1: [3]Januari!$O$2
Name KustomKunci2: [3]Januari!$S$2
Name LiburanKunci: [3]Januari!$D$2
Name PribadiKunci: [3]Januari!$H$2
Name SakitKunci: [3]Januari!$L$2
Name TahunKalender: [3]Januari!$AI$4

Sheet PELANGI 02
B1: LOKASI | D1: PELANGI 02 | H1: TYPE | J1: 50
B4: No. | C4: URAIAN PEKERJAAN | D4: BAHAN | F4: HARGA BAHAN | G4: TOTAL HARGA | H4: UPAH | I4: BORONGAN | J4: UNTUNG/RUGI | K4: PROGRES
D5: BAKU | E5: OUT | F5: ( Rp ) | G5: ( Rp )
B6: A | C6: PONDASI
B7: 1 | C7: Besi ø6 | D7: =IFERROR(HLOOKUP($J$1,[1]DB!$C$1:$K$172,7,FALSE),"") -> 12 | E7: =SUMIFS('[1]Rincian Keluar'!$G:$G,'[1]Rincian Keluar'!$E:$E,'PELANGI 02'!C7,'[1]Rincian Keluar'!$D:$D,'PELANGI 02'!$D$1,'[1]Rincian Keluar'!$H:$H,'PELANGI 02'!$J$1,'[1]Rincian Keluar'!$F:$F,'PELANGI 02'!M7) -> 12 | F7: 21500 | G7: =E7*F7 -> 258000 | H7: 2000000 | I7: =IFERROR(VLOOKUP($C6,[1]HK!$B$5:$C$14,2,FALSE),"")*$J1 -> 2085000 | J7: =I7-H7 -> 85000 | K7: 1 | M7: =$C$6 -> PONDASI
B8: 2 | C8: Besi ø8 Ulir | D8: =IFERROR(HLOOKUP($J$1,[1]DB!$C$1:$K$172,8,FALSE),"") -> 41 | E8: =SUMIFS('[1]Rincian Keluar'!$G:$G,'[1]Rincian Keluar'!$E:$E,'PELANGI 02'!C8,'[1]Rincian Keluar'!$D:$D,'PELANGI 02'!$D$1,'[1]Rincian Keluar'!$H:$H,'PELANGI 02'!$J$1,'[1]Rincian Keluar'!$F:$F,'PELANGI 02'!M8) -> 41 | F8: 49000 | G8: =E8*F8 -> 2009000 | M8: =$C$6 -> PONDASI
B9: 3 | C9: Kayu 3/5 | D9: =IFERROR(HLOOKUP($J$1,[1]DB!$C$1:$K$172,9,FALSE),"") -> 35 | E9: =SUMIFS('[1]Rincian Keluar'!$G:$G,'[1]Rincian Keluar'!$E:$E,'PELANGI 02'!C9,'[1]Rincian Keluar'!$D:$D,'PELANGI 02'!$D$1,'[1]Rincian Keluar'!$H:$H,'PELANGI 02'!$J$1,'[1]Rincian Keluar'!$F:$F,'PELANGI 02'!M9) -> 35 | F9: 11000 | G9: =E9*F9 -> 385000 | M9: =$C$6 -> PONDASI
B10: 4 | C10: Cerucuk | D10: =IFERROR(HLOOKUP($J$1,[1]DB!$C$1:$K$172,10,FALSE),"") -> 74 | E10: =SUMIFS('[1]Rincian Keluar'!$G:$G,'[1]Rincian Keluar'!$E:$E,'PELANGI 02'!C10,'[1]Rincian Keluar'!$D:$D,'PELANGI 02'!$D$1,'[1]Rincian Keluar'!$H:$H,'PELANGI 02'!$J$1,'[1]Rincian Keluar'!$F:$F,'PELANGI 02'!M10) -> 75 | F10: 8000 | G10: =E10*F10 -> 600000 | M10: =$C$6 -> PONDASI
B11: 5 | C11: Papan Mal | D11: =IFERROR(HLOOKUP($J$1,[1]DB!$C$1:$K$172,11,FALSE),"") -> 164 | E11: =SUMIFS('[1]Rincian Keluar'!$G:$G,'[1]Rincian Keluar'!$E:$E,'PELANGI 02'!C11,'[1]Rincian Keluar'!$D:$D,'PELANGI 02'!$D$1,'[1]Rincian Keluar'!$H:$H,'PELANGI 02'!$J$1,'[1]Rincian Keluar'!$F:$F,'PELANGI 02'!M11) -> 23 | F11: 11000 | G11: =E11*F11 -> 253000 | M11: =$C$6 -> PONDASI
B12: 6 | C12: Pasir | D12: =IFERROR(HLOOKUP($J$1,[1]DB!$C$1:$K$172,12,FALSE),"") -> 13 | E12: =SUMIFS('[1]Rincian Keluar'!$G:$G,'[1]Rincian Keluar'!$E:$E,'PELANGI 02'!C12,'[1]Rincian Keluar'!$D:$D,'PELANGI 02'!$D$1,'[1]Rincian Keluar'!$H:$H,'PELANGI 02'!$J$1,'[1]Rincian Keluar'!$F:$F,'PELANGI 02'!M12) -> 0 | F12: 150000 | G12: =E12*F12 -> 0 | M12: =$C$6 -> PONDASI
B13: 7 | C13: Batu | D13: =IFERROR(HLOOKUP($J$1,[1]DB!$C$1:$K$172,13,FALSE),"") -> 2 | E13: =SUMIFS('[1]Rincian Keluar'!$G:$G,'[1]Rincian Keluar'!$E:$E,'PELANGI 02'!C13,'[1]Rincian Keluar'!$D:$D,'PELANGI 02'!$D$1,'[1]Rincian Keluar'!$H:$H,'PELANGI 02'!$J$1,'[1]Rincian Keluar'!$F:$F,'PELANGI 02'!M13) -> 2 | F13: 500000 | G13: =E13*F13 -> 1000000 | M13: =$C$6 -> PONDASI
B14: 8 | C14: Semen PCC 40 Kg Tiga Roda | D14: =IFERROR(HLOOKUP($J$1,[1]DB!$C$1:$K$172,14,FALSE),"") -> 38 | E14: =SUMIFS('[1]Rincian Keluar'!$G:$G,'[1]Rincian Keluar'!$E:$E,'PELANGI 02'!C14,'[1]Rincian Keluar'!$D:$D,'PELANGI 02'!$D$1,'[1]Rincian Keluar'!$H:$H,'PELANGI 02'!$J$1,'[1]Rincian Keluar'!$F:$F,'PELANGI 02'!M14) -> 42 | F14: 60700 | G14: =E14*F14 -> 2549400 | M14: =$C$6 -> PONDASI
B15: B | C15: URUG
B16: 1 | C16: Pasir | D16: =IFERROR(HLOOKUP($J$1,[1]DB!$C$1:$K$172,16,FALSE),"") -> 32 | E16: =SUMIFS('[1]Rincian Keluar'!$G:$G,'[1]Rincian Keluar'!$E:$E,'PELANGI 02'!C16,'[1]Rincian Keluar'!$D:$D,'PELANGI 02'!$D$1,'[1]Rincian Keluar'!$H:$H,'PELANGI 02'!$J$1,'[1]Rincian Keluar'!$F:$F,'PELANGI 02'!M16) -> 14 | F16: 150000 | G16: =E16*F16 -> 2100000 | H16: 819000 | I16: =IFERROR(VLOOKUP($C15,[1]HK!$B$5:$C$14,2,FALSE),"")*$J1 -> 835000 | J16: =I16-H16 -> 16000 | K16: 1 | M16: =$C$15 -> URUG
B17: 2 | C17: Pipa 4" | D17: =IFERROR(HLOOKUP($J$1,[1]DB!$C$1:$K$172,17,FALSE),"") -> 2 | E17: =SUMIFS('[1]Rincian Keluar'!$G:$G,'[1]Rincian Keluar'!$E:$E,'PELANGI 02'!C17,'[1]Rincian Keluar'!$D:$D,'PELANGI 02'!$D$1,'[1]Rincian Keluar'!$H:$H,'PELANGI 02'!$J$1,'[1]Rincian Keluar'!$F:$F,'PELANGI 02'!M17) -> 2 | F17: 133500 | G17: =E17*F17 -> 267000 | M17: =$C$15 -> URUG
B18: 3 | C18: Pipa 2" | D18: =IFERROR(HLOOKUP($J$1,[1]DB!$C$1:$K$172,18,FALSE),"") -> 2 | E18: =SUMIFS('[1]Rincian Keluar'!$G:$G,'[1]Rincian Keluar'!$E:$E,'PELANGI 02'!C18,'[1]Rincian Keluar'!$D:$D,'PELANGI 02'!$D$1,'[1]Rincian Keluar'!$H:$H,'PELANGI 02'!$J$1,'[1]Rincian Keluar'!$F:$F,'PELANGI 02'!M18) -> 2 | F18: 48000 | G18: =E18*F18 -> 96000 | M18: =$C$15 -> URUG
B19: C | C19: COR LANTAI
B20: 1 | C20: Besi ø6 | D20: =IFERROR(HLOOKUP($J$1,[1]DB!$C$1:$K$172,20,FALSE),"") -> 15 | E20: =SUMIFS('[1]Rincian Keluar'!$G:$G,'[1]Rincian Keluar'!$E:$E,'PELANGI 02'!C20,'[1]Rincian Keluar'!$D:$D,'PELANGI 02'!$D$1,'[1]Rincian Keluar'!$H:$H,'PELANGI 02'!$J$1,'[1]Rincian Keluar'!$F:$F,'PELANGI 02'!M20) -> 15 | F20: 22000 | G20: =E20*F20 -> 330000 | H20: 504000 | I20: =IFERROR(VLOOKUP($C19,[1]HK!$B$5:$C$14,2,FALSE),"")*$J1 -> 500000 | J20: =I20-H20 -> -4000 | K20: 1 | M20: =$C$19 -> COR LANTAI
B21: 2 | C21: Pasir | D21: =IFERROR(HLOOKUP($J$1,[1]DB!$C$1:$K$172,21,FALSE),"") -> 5 | E21: =SUMIFS('[1]Rincian Keluar'!$G:$G,'[1]Rincian Keluar'!$E:$E,'PELANGI 02'!C21,'[1]Rincian Keluar'!$D:$D,'PELANGI 02'!$D$1,'[1]Rincian Keluar'!$H:$H,'PELANGI 02'!$J$1,'[1]Rincian Keluar'!$F:$F,'PELANGI 02'!M21) -> 2 | F21: 150000 | G21: =E21*F21 -> 300000 | M21: =$C$19 -> COR LANTAI
B22: 3 | C22: Semen PCC 40 Kg Tiga Roda | D22: =IFERROR(HLOOKUP($J$1,[1]DB!$C$1:$K$172,22,FALSE),"") -> 14 | E22: =SUMIFS('[1]Rincian Keluar'!$G:$G,'[1]Rincian Keluar'!$E:$E,'PELANGI 02'!C22,'[1]Rincian Keluar'!$D:$D,'PELANGI 02'!$D$1,'[1]Rincian Keluar'!$H:$H,'PELANGI 02'!$J$1,'[1]Rincian Keluar'!$F:$F,'PELANGI 02'!M22) -> 9 | F22: 60700 | G22: =E22*F22 -> 546300 | M22: =$C$19 -> COR LANTAI
B23: 4 | C23: Plastik cor | D23: =IFERROR(HLOOKUP($J$1,[1]DB!$C$1:$K$172,23,FALSE),"") -> 6 | E23: =SUMIFS('[1]Rincian Keluar'!$G:$G,'[1]Rincian Keluar'!$E:$E,'PELANGI 02'!C23,'[1]Rincian Keluar'!$D:$D,'PELANGI 02'!$D$1,'[1]Rincian Keluar'!$H:$H,'PELANGI 02'!$J$1,'[1]Rincian Keluar'!$F:$F,'PELANGI 02'!M23) -> 6 | F23: 15000 | G23: =E23*F23 -> 90000 | M23: =$C$19 -> COR LANTAI
B24: D | C24: PINTU
B25: 1 | C25: Pintu Kayu 120 x 220 | D25: =IFERROR(HLOOKUP($J$1,[1]DB!$C$1:$K$172,25,FALSE),"") -> 1 | E25: =SUMIFS('[1]Rincian Keluar'!$G:$G,'[1]Rincian Keluar'!$E:$E,'PELANGI 02'!C25,'[1]Rincian Keluar'!$D:$D,'PELANGI 02'!$D$1,'[1]Rincian Keluar'!$H:$H,'PELANGI 02'!$J$1,'[1]Rincian Keluar'!$F:$F,'PELANGI 02'!M25) -> 0 | F25: 1550000 | G25: =E25*F25 -> 0 | I25: =IFERROR(VLOOKUP($C24,[1]HK!$B$5:$C$14,2,FALSE),"")*$J1 -> #VALUE! | M25: =$C$24 -> PINTU
B26: 2 | C26: Pintu Kayu 80 x 220 | D26: =IFERROR(HLOOKUP($J$1,[1]DB!$C$1:$K$172,26,FALSE),"") -> 3 | E26: =SUMIFS('[1]Rincian Keluar'!$G:$G,'[1]Rincian Keluar'!$E:$E,'PELANGI 02'!C26,'[1]Rincian Keluar'!$D:$D,'PELANGI 02'!$D$1,'[1]Rincian Keluar'!$H:$H,'PELANGI 02'!$J$1,'[1]Rincian Keluar'!$F:$F,'PELANGI 02'!M26) -> 0 | F26: 775000 | G26: =E26*F26 -> 0 | M26: =$C$24 -> PINTU
B27: 3 | C27: Pintu WC PVC Biru | D27: =IFERROR(HLOOKUP($J$1,[1]DB!$C$1:$K$172,27,FALSE),"") -> 2 | E27: =SUMIFS('[1]Rincian Keluar'!$G:$G,'[1]Rincian Keluar'!$E:$E,'PELANGI 02'!C27,'[1]Rincian Keluar'!$D:$D,'PELANGI 02'!$D$1,'[1]Rincian Keluar'!$H:$H,'PELANGI 02'!$J$1,'[1]Rincian Keluar'!$F:$F,'PELANGI 02'!M27) -> 0 | F27: 260000 | G27: =E27*F27 -> 0 | M27: =$C$24 -> PINTU
B28: 4 | C28: Pintu WC Edenjoice Putih | D28: =IFERROR(HLOOKUP($J$1,[1]DB!$C$1:$K$172,28,FALSE),"") -> 1 | E28: =SUMIFS('[1]Rincian Keluar'!$G:$G,'[1]Rincian Keluar'!$E:$E,'PELANGI 02'!C28,'[1]Rincian Keluar'!$D:$D,'PELANGI 02'!$D$1,'[1]Rincian Keluar'!$H:$H,'PELANGI 02'!$J$1,'[1]Rincian Keluar'!$F:$F,'PELANGI 02'!M28) -> 0 | F28: 799000 | G28: =E28*F28 -> 0 | M28: =$C$24 -> PINTU
B29: 5 | C29: Engsel Pintu 4" | D29: =IFERROR(HLOOKUP($J$1,[1]DB!$C$1:$K$172,29,FALSE),"") -> 15 | E29: =SUMIFS('[1]Rincian Keluar'!$G:$G,'[1]Rincian Keluar'!$E:$E,'PELANGI 02'!C29,'[1]Rincian Keluar'!$D:$D,'PELANGI 02'!$D$1,'[1]Rincian Keluar'!$H:$H,'PELANGI 02'!$J$1,'[1]Rincian Keluar'!$F:$F,'PELANGI 02'!M29) -> 0 | F29: 15000 | G29: =E29*F29 -> 0 | M29: =$C$24 -> PINTU
B30: 6 | C30: Peganggan pintu 2 daun | D30: =IFERROR(HLOOKUP($J$1,[1]DB!$C$1:$K$172,30,FALSE),"") -> 2 | E30: =SUMIFS('[1]Rincian Keluar'!$G:$G,'[1]Rincian Keluar'!$E:$E,'PELANGI 02'!C30,'[1]Rincian Keluar'!$D:$D,'PELANGI 02'!$D$1,'[1]Rincian Keluar'!$H:$H,'PELANGI 02'!$J$1,'[1]Rincian Keluar'!$F:$F,'PELANGI 02'!M30) -> 0 | F30: 100000 | G30: =E30*F30 -> 0 | M30: =$C$24 -> PINTU
B31: 7 | C31: Pengunci Pintu 2 daun | D31: =IFERROR(HLOOKUP($J$1,[1]DB!$C$1:$K$172,31,FALSE),"") -> 1 | E31: =SUMIFS('[1]Rincian Keluar'!$G:$G,'[1]Rincian Keluar'!$E:$E,'PELANGI 02'!C31,'[1]Rincian Keluar'!$D:$D,'PELANGI 02'!$D$1,'[1]Rincian Keluar'!$H:$H,'PELANGI 02'!$J$1,'[1]Rincian Keluar'!$F:$F,'PELANGI 02'!M31) -> 0 | F31: 60000 | G31: =E31*F31 -> 0 | M31: =$C$24 -> PINTU
B32: 8 | C32: Pegangan kunci 1 daun | D32: =IFERROR(HLOOKUP($J$1,[1]DB!$C$1:$K$172,32,FALSE),"") -> 3 | E32: =SUMIFS('[1]Rincian Keluar'!$G:$G,'[1]Rincian Keluar'!$E:$E,'PELANGI 02'!C32,'[1]Rincian Keluar'!$D:$D,'PELANGI 02'!$D$1,'[1]Rincian Keluar'!$H:$H,'PELANGI 02'!$J$1,'[1]Rincian Keluar'!$F:$F,'PELANGI 02'!M32) -> 0 | F32: 65000 | G32: =E32*F32 -> 0 | M32: =$C$24 -> PINTU
B33: 9 | C33: Avian | D33: =IFERROR(HLOOKUP($J$1,[1]DB!$C$1:$K$172,33,FALSE),"") -> 4 | E33: =SUMIFS('[1]Rincian Keluar'!$G:$G,'[1]Rincian Keluar'!$E:$E,'PELANGI 02'!C33,'[1]Rincian Keluar'!$D:$D,'PELANGI 02'!$D$1,'[1]Rincian Keluar'!$H:$H,'PELANGI 02'!$J$1,'[1]Rincian Keluar'!$F:$F,'PELANGI 02'!M33) -> 0 | F33: 83000 | G33: =E33*F33 -> 0 | M33: =$C$24 -> PINTU
B34: 10 | C34: Tinner Nb Kaleng | D34: =IFERROR(HLOOKUP($J$1,[1]DB!$C$1:$K$172,34,FALSE),"") -> 2 | E34: =SUMIFS('[1]Rincian Keluar'!$G:$G,'[1]Rincian Keluar'!$E:$E,'PELANGI 02'!C34,'[1]Rincian Keluar'!$D:$D,'PELANGI 02'!$D$1,'[1]Rincian Keluar'!$H:$H,'PELANGI 02'!$J$1,'[1]Rincian Keluar'!$F:$F,'PELANGI 02'!M34) -> 0 | F34: 23000 | G34: =E34*F34 -> 0 | M34: =$C$24 -> PINTU
B35: 11 | C35: Slot 6 " | D35: =IFERROR(HLOOKUP($J$1,[1]DB!$C$1:$K$172,35,FALSE),"") -> 1 | E35: =SUMIFS('[1]Rincian Keluar'!$G:$G,'[1]Rincian Keluar'!$E:$E,'PELANGI 02'!C35,'[1]Rincian Keluar'!$D:$D,'PELANGI 02'!$D$1,'[1]Rincian Keluar'!$H:$H,'PELANGI 02'!$J$1,'[1]Rincian Keluar'!$F:$F,'PELANGI 02'!M35) -> 0 | F35: 17000 | G35: =E35*F35 -> 0 | M35: =$C$24 -> PINTU
B36: 12 | C36: Slot 4" | D36: =IFERROR(HLOOKUP($J$1,[1]DB!$C$1:$K$172,36,FALSE),"") -> 1 | E36: =SUMIFS('[1]Rincian Keluar'!$G:$G,'[1]Rincian Keluar'!$E:$E,'PELANGI 02'!C36,'[1]Rincian Keluar'!$D:$D,'PELANGI 02'!$D$1,'[1]Rincian Keluar'!$H:$H,'PELANGI 02'!$J$1,'[1]Rincian Keluar'!$F:$F,'PELANGI 02'!M36) -> 0 | F36: 11000 | G36: =E36*F36 -> 0 | M36: =$C$24 -> PINTU
B37: E | C37: BATA
B38: 1 | C38: Papan | D38: =IFERROR(HLOOKUP($J$1,[1]DB!$C$1:$K$172,38,FALSE),"") -> 24 | E38: =SUMIFS('[1]Rincian Keluar'!$G:$G,'[1]Rincian Keluar'!$E:$E,'PELANGI 02'!C38,'[1]Rincian Keluar'!$D:$D,'PELANGI 02'!$D$1,'[1]Rincian Keluar'!$H:$H,'PELANGI 02'!$J$1,'[1]Rincian Keluar'!$F:$F,'PELANGI 02'!M38) -> 34 | F38: 11000 | G38: =E38*F38 -> 374000 | H38: 720000 | I38: =IFERROR(VLOOKUP($C37,[1]HK!$B$5:$C$14,2,FALSE),"")*$J1 -> 3475000 | J38: =I38-H38 -> 2755000 | K38: 0.2 | M38: =$C$37 -> BATA
B39: 2 | C39: Kayu 3/5 | D39: =IFERROR(HLOOKUP($J$1,[1]DB!$C$1:$K$172,39,FALSE),"") -> 25 | E39: =SUMIFS('[1]Rincian Keluar'!$G:$G,'[1]Rincian Keluar'!$E:$E,'PELANGI 02'!C39,'[1]Rincian Keluar'!$D:$D,'PELANGI 02'!$D$1,'[1]Rincian Keluar'!$H:$H,'PELANGI 02'!$J$1,'[1]Rincian Keluar'!$F:$F,'PELANGI 02'!M39) -> 36 | F39: 11000 | G39: =E39*F39 -> 396000 | M39: =$C$37 -> BATA
B40: 3 | C40: Besi ø6 | D40: =IFERROR(HLOOKUP($J$1,[1]DB!$C$1:$K$172,40,FALSE),"") -> 5 | E40: =SUMIFS('[1]Rincian Keluar'!$G:$G,'[1]Rincian Keluar'!$E:$E,'PELANGI 02'!C40,'[1]Rincian Keluar'!$D:$D,'PELANGI 02'!$D$1,'[1]Rincian Keluar'!$H:$H,'PELANGI 02'!$J$1,'[1]Rincian Keluar'!$F:$F,'PELANGI 02'!M40) -> 5 | F40: 22000 | G40: =E40*F40 -> 110000 | M40: =$C$37 -> BATA
B41: 4 | C41: Besi ø8 | D41: =IFERROR(HLOOKUP($J$1,[1]DB!$C$1:$K$172,41,FALSE),"") -> 8 | E41: =SUMIFS('[1]Rincian Keluar'!$G:$G,'[1]Rincian Keluar'!$E:$E,'PELANGI 02'!C41,'[1]Rincian Keluar'!$D:$D,'PELANGI 02'!$D$1,'[1]Rincian Keluar'!$H:$H,'PELANGI 02'!$J$1,'[1]Rincian Keluar'!$F:$F,'PELANGI 02'!M41) -> 8 | F41: 35000 | G41: =E41*F41 -> 280000 | M41: =$C$37 -> BATA
B42: 5 | C42: Besi ø6 | D42: =IFERROR(HLOOKUP($J$1,[1]DB!$C$1:$K$172,42,FALSE),"") -> 2 | E42: =SUMIFS('[1]Rincian Keluar'!$G:$G,'[1]Rincian Keluar'!$E:$E,'PELANGI 02'!C42,'[1]Rincian Keluar'!$D:$D,'PELANGI 02'!$D$1,'[1]Rincian Keluar'!$H:$H,'PELANGI 02'!$J$1,'[1]Rincian Keluar'!$F:$F,'PELANGI 02'!M42) -> 2 | F42: =F40 -> 22000 | G42: =E42*F42 -> 44000 | M42: =$C$37 -> BATA
...

Sheet RIDHO 01
B1: LOKASI | D1: RIDHO 01 | H1: TYPE | J1: 80
B4: No. | C4: URAIAN PEKERJAAN | D4: BAHAN | F4: HARGA BAHAN | G4: TOTAL HARGA | H4: UPAH | I4: BORONGAN | J4: UNTUNG/RUGI | K4: PROGRES
D5: BAKU | E5: OUT | F5: ( Rp ) | G5: ( Rp )
B6: A | C6: PONDASI
B7: 1 | C7: Besi ø6 | D7: =IFERROR(HLOOKUP($J$1,[1]DB!$C$1:$K$172,7,FALSE),"") -> 19 | E7: =SUMIFS('[1]Rincian Keluar'!$G:$G,'[1]Rincian Keluar'!$E:$E,'RIDHO 01'!C7,'[1]Rincian Keluar'!$D:$D,'RIDHO 01'!$D$1,'[1]Rincian Keluar'!$H:$H,'RIDHO 01'!$J$1,'[1]Rincian Keluar'!$F:$F,'RIDHO 01'!M7) -> 16 | F7: 21500 | G7: =E7*F7 -> 344000 | H7: 2565000 | I7: =IFERROR(VLOOKUP($C6,[1]HK!$B$5:$C$14,2,FALSE),"")*$J1 -> 3336000 | J7: =I7-H7 -> 771000 | K7: 1 | M7: =$C$6 -> PONDASI
B8: 2 | C8: Besi ø8 Ulir | D8: =IFERROR(HLOOKUP($J$1,[1]DB!$C$1:$K$172,8,FALSE),"") -> 66 | E8: =SUMIFS('[1]Rincian Keluar'!$G:$G,'[1]Rincian Keluar'!$E:$E,'RIDHO 01'!C8,'[1]Rincian Keluar'!$D:$D,'RIDHO 01'!$D$1,'[1]Rincian Keluar'!$H:$H,'RIDHO 01'!$J$1,'[1]Rincian Keluar'!$F:$F,'RIDHO 01'!M8) -> 56 | F8: 49000 | G8: =E8*F8 -> 2744000 | M8: =$C$6 -> PONDASI
B9: 3 | C9: Kayu 3/5 | D9: =IFERROR(HLOOKUP($J$1,[1]DB!$C$1:$K$172,9,FALSE),"") -> 56 | E9: =SUMIFS('[1]Rincian Keluar'!$G:$G,'[1]Rincian Keluar'!$E:$E,'RIDHO 01'!C9,'[1]Rincian Keluar'!$D:$D,'RIDHO 01'!$D$1,'[1]Rincian Keluar'!$H:$H,'RIDHO 01'!$J$1,'[1]Rincian Keluar'!$F:$F,'RIDHO 01'!M9) -> 42 | F9: 11000 | G9: =E9*F9 -> 462000 | M9: =$C$6 -> PONDASI
B10: 4 | C10: Cerucuk | D10: =IFERROR(HLOOKUP($J$1,[1]DB!$C$1:$K$172,10,FALSE),"") -> 118 | E10: =SUMIFS('[1]Rincian Keluar'!$G:$G,'[1]Rincian Keluar'!$E:$E,'RIDHO 01'!C10,'[1]Rincian Keluar'!$D:$D,'RIDHO 01'!$D$1,'[1]Rincian Keluar'!$H:$H,'RIDHO 01'!$J$1,'[1]Rincian Keluar'!$F:$F,'RIDHO 01'!M10) -> 89 | F10: 8000 | G10: =E10*F10 -> 712000 | M10: =$C$6 -> PONDASI
B11: 5 | C11: Papan Mal | D11: =IFERROR(HLOOKUP($J$1,[1]DB!$C$1:$K$172,11,FALSE),"") -> 262 | E11: =SUMIFS('[1]Rincian Keluar'!$G:$G,'[1]Rincian Keluar'!$E:$E,'RIDHO 01'!C11,'[1]Rincian Keluar'!$D:$D,'RIDHO 01'!$D$1,'[1]Rincian Keluar'!$H:$H,'RIDHO 01'!$J$1,'[1]Rincian Keluar'!$F:$F,'RIDHO 01'!M11) -> 197 | F11: 11000 | G11: =E11*F11 -> 2167000 | M11: =$C$6 -> PONDASI
B12: 6 | C12: Pasir | D12: =IFERROR(HLOOKUP($J$1,[1]DB!$C$1:$K$172,12,FALSE),"") -> 21 | E12: =SUMIFS('[1]Rincian Keluar'!$G:$G,'[1]Rincian Keluar'!$E:$E,'RIDHO 01'!C12,'[1]Rincian Keluar'!$D:$D,'RIDHO 01'!$D$1,'[1]Rincian Keluar'!$H:$H,'RIDHO 01'!$J$1,'[1]Rincian Keluar'!$F:$F,'RIDHO 01'!M12) -> 17 | F12: 150000 | G12: =E12*F12 -> 2550000 | M12: =$C$6 -> PONDASI
B13: 7 | C13: Batu | D13: =IFERROR(HLOOKUP($J$1,[1]DB!$C$1:$K$172,13,FALSE),"") -> 3 | E13: =SUMIFS('[1]Rincian Keluar'!$G:$G,'[1]Rincian Keluar'!$E:$E,'RIDHO 01'!C13,'[1]Rincian Keluar'!$D:$D,'RIDHO 01'!$D$1,'[1]Rincian Keluar'!$H:$H,'RIDHO 01'!$J$1,'[1]Rincian Keluar'!$F:$F,'RIDHO 01'!M13) -> 3 | F13: 500000 | G13: =E13*F13 -> 1500000 | M13: =$C$6 -> PONDASI
B14: 8 | C14: Semen PCC 40 Kg Tiga Roda | D14: =IFERROR(HLOOKUP($J$1,[1]DB!$C$1:$K$172,14,FALSE),"") -> 62 | E14: =SUMIFS('[1]Rincian Keluar'!$G:$G,'[1]Rincian Keluar'!$E:$E,'RIDHO 01'!C14,'[1]Rincian Keluar'!$D:$D,'RIDHO 01'!$D$1,'[1]Rincian Keluar'!$H:$H,'RIDHO 01'!$J$1,'[1]Rincian Keluar'!$F:$F,'RIDHO 01'!M14) -> 51 | F14: 60700 | G14: =E14*F14 -> 3095700 | M14: =$C$6 -> PONDASI
B15: B | C15: URUG
B16: 1 | C16: Pasir | D16: =IFERROR(HLOOKUP($J$1,[1]DB!$C$1:$K$172,16,FALSE),"") -> 51 | E16: =SUMIFS('[1]Rincian Keluar'!$G:$G,'[1]Rincian Keluar'!$E:$E,'RIDHO 01'!C16,'[1]Rincian Keluar'!$D:$D,'RIDHO 01'!$D$1,'[1]Rincian Keluar'!$H:$H,'RIDHO 01'!$J$1,'[1]Rincian Keluar'!$F:$F,'RIDHO 01'!M16) -> 47 | F16: 150000 | G16: =E16*F16 -> 7050000 | H16: 1087000 | I16: =IFERROR(VLOOKUP($C15,[1]HK!$B$5:$C$14,2,FALSE),"")*$J1 -> 1336000 | J16: =I16-H16 -> 249000 | K16: 1 | M16: =$C$15 -> URUG
B17: 2 | C17: Pipa 4" | D17: =IFERROR(HLOOKUP($J$1,[1]DB!$C$1:$K$172,17,FALSE),"") -> 2 | E17: =SUMIFS('[1]Rincian Keluar'!$G:$G,'[1]Rincian Keluar'!$E:$E,'RIDHO 01'!C17,'[1]Rincian Keluar'!$D:$D,'RIDHO 01'!$D$1,'[1]Rincian Keluar'!$H:$H,'RIDHO 01'!$J$1,'[1]Rincian Keluar'!$F:$F,'RIDHO 01'!M17) -> 2 | F17: 133500 | G17: =E17*F17 -> 267000 | M17: =$C$15 -> URUG
B18: 3 | C18: Pipa 2" | D18: =IFERROR(HLOOKUP($J$1,[1]DB!$C$1:$K$172,18,FALSE),"") -> 2 | E18: =SUMIFS('[1]Rincian Keluar'!$G:$G,'[1]Rincian Keluar'!$E:$E,'RIDHO 01'!C18,'[1]Rincian Keluar'!$D:$D,'RIDHO 01'!$D$1,'[1]Rincian Keluar'!$H:$H,'RIDHO 01'!$J$1,'[1]Rincian Keluar'!$F:$F,'RIDHO 01'!M18) -> 2 | F18: 48000 | G18: =E18*F18 -> 96000 | M18: =$C$15 -> URUG
B19: C | C19: COR LANTAI
B20: 1 | C20: Besi ø6 | D20: =IFERROR(HLOOKUP($J$1,[1]DB!$C$1:$K$172,20,FALSE),"") -> 25 | E20: =SUMIFS('[1]Rincian Keluar'!$G:$G,'[1]Rincian Keluar'!$E:$E,'RIDHO 01'!C20,'[1]Rincian Keluar'!$D:$D,'RIDHO 01'!$D$1,'[1]Rincian Keluar'!$H:$H,'RIDHO 01'!$J$1,'[1]Rincian Keluar'!$F:$F,'RIDHO 01'!M20) -> 25 | F20: 22000 | G20: =E20*F20 -> 550000 | H20: 879000 | I20: =IFERROR(VLOOKUP($C19,[1]HK!$B$5:$C$14,2,FALSE),"")*$J1 -> 800000 | J20: =I20-H20 -> -79000 | K20: 1 | M20: =$C$19 -> COR LANTAI
B21: 2 | C21: Pasir | D21: =IFERROR(HLOOKUP($J$1,[1]DB!$C$1:$K$172,21,FALSE),"") -> 8 | E21: =SUMIFS('[1]Rincian Keluar'!$G:$G,'[1]Rincian Keluar'!$E:$E,'RIDHO 01'!C21,'[1]Rincian Keluar'!$D:$D,'RIDHO 01'!$D$1,'[1]Rincian Keluar'!$H:$H,'RIDHO 01'!$J$1,'[1]Rincian Keluar'!$F:$F,'RIDHO 01'!M21) -> 7 | F21: 150000 | G21: =E21*F21 -> 1050000 | M21: =$C$19 -> COR LANTAI
B22: 3 | C22: Semen PCC 40 Kg Tiga Roda | D22: =IFERROR(HLOOKUP($J$1,[1]DB!$C$1:$K$172,22,FALSE),"") -> 22 | E22: =SUMIFS('[1]Rincian Keluar'!$G:$G,'[1]Rincian Keluar'!$E:$E,'RIDHO 01'!C22,'[1]Rincian Keluar'!$D:$D,'RIDHO 01'!$D$1,'[1]Rincian Keluar'!$H:$H,'RIDHO 01'!$J$1,'[1]Rincian Keluar'!$F:$F,'RIDHO 01'!M22) -> 24 | F22: 60700 | G22: =E22*F22 -> 1456800 | M22: =$C$19 -> COR LANTAI
B23: 4 | C23: Plastik cor | D23: =IFERROR(HLOOKUP($J$1,[1]DB!$C$1:$K$172,23,FALSE),"") -> 11 | E23: =SUMIFS('[1]Rincian Keluar'!$G:$G,'[1]Rincian Keluar'!$E:$E,'RIDHO 01'!C23,'[1]Rincian Keluar'!$D:$D,'RIDHO 01'!$D$1,'[1]Rincian Keluar'!$H:$H,'RIDHO 01'!$J$1,'[1]Rincian Keluar'!$F:$F,'RIDHO 01'!M23) -> 8 | F23: 15000 | G23: =E23*F23 -> 120000 | M23: =$C$19 -> COR LANTAI
B24: D | C24: PINTU
B25: 1 | C25: Pintu Kayu 120 x 220 | D25: =IFERROR(HLOOKUP($J$1,[1]DB!$C$1:$K$172,25,FALSE),"") -> 2 | E25: =SUMIFS('[1]Rincian Keluar'!$G:$G,'[1]Rincian Keluar'!$E:$E,'RIDHO 01'!C25,'[1]Rincian Keluar'!$D:$D,'RIDHO 01'!$D$1,'[1]Rincian Keluar'!$H:$H,'RIDHO 01'!$J$1,'[1]Rincian Keluar'!$F:$F,'RIDHO 01'!M25) -> 0 | F25: 1550000 | G25: =E25*F25 -> 0 | I25: =IFERROR(VLOOKUP($C24,[1]HK!$B$5:$C$14,2,FALSE),"")*$J1 -> #VALUE! | M25: =$C$24 -> PINTU
B26: 2 | C26: Pintu Kayu 80 x 220 | D26: =IFERROR(HLOOKUP($J$1,[1]DB!$C$1:$K$172,26,FALSE),"") -> 3 | E26: =SUMIFS('[1]Rincian Keluar'!$G:$G,'[1]Rincian Keluar'!$E:$E,'RIDHO 01'!C26,'[1]Rincian Keluar'!$D:$D,'RIDHO 01'!$D$1,'[1]Rincian Keluar'!$H:$H,'RIDHO 01'!$J$1,'[1]Rincian Keluar'!$F:$F,'RIDHO 01'!M26) -> 0 | F26: 775000 | G26: =E26*F26 -> 0 | M26: =$C$24 -> PINTU
B27: 3 | C27: Pintu WC PVC Biru | D27: =IFERROR(HLOOKUP($J$1,[1]DB!$C$1:$K$172,27,FALSE),"") -> 2 | E27: =SUMIFS('[1]Rincian Keluar'!$G:$G,'[1]Rincian Keluar'!$E:$E,'RIDHO 01'!C27,'[1]Rincian Keluar'!$D:$D,'RIDHO 01'!$D$1,'[1]Rincian Keluar'!$H:$H,'RIDHO 01'!$J$1,'[1]Rincian Keluar'!$F:$F,'RIDHO 01'!M27) -> 0 | F27: 260000 | G27: =E27*F27 -> 0 | M27: =$C$24 -> PINTU
B28: 4 | C28: Pintu WC Edenjoice Putih | D28: =IFERROR(HLOOKUP($J$1,[1]DB!$C$1:$K$172,28,FALSE),"") -> 1 | E28: =SUMIFS('[1]Rincian Keluar'!$G:$G,'[1]Rincian Keluar'!$E:$E,'RIDHO 01'!C28,'[1]Rincian Keluar'!$D:$D,'RIDHO 01'!$D$1,'[1]Rincian Keluar'!$H:$H,'RIDHO 01'!$J$1,'[1]Rincian Keluar'!$F:$F,'RIDHO 01'!M28) -> 0 | F28: 799000 | G28: =E28*F28 -> 0 | M28: =$C$24 -> PINTU
B29: 5 | C29: Engsel Pintu 4" | D29: =IFERROR(HLOOKUP($J$1,[1]DB!$C$1:$K$172,29,FALSE),"") -> 15 | E29: =SUMIFS('[1]Rincian Keluar'!$G:$G,'[1]Rincian Keluar'!$E:$E,'RIDHO 01'!C29,'[1]Rincian Keluar'!$D:$D,'RIDHO 01'!$D$1,'[1]Rincian Keluar'!$H:$H,'RIDHO 01'!$J$1,'[1]Rincian Keluar'!$F:$F,'RIDHO 01'!M29) -> 0 | F29: 15000 | G29: =E29*F29 -> 0 | M29: =$C$24 -> PINTU
B30: 6 | C30: Peganggan pintu 2 daun | D30: =IFERROR(HLOOKUP($J$1,[1]DB!$C$1:$K$172,30,FALSE),"") -> 2 | E30: =SUMIFS('[1]Rincian Keluar'!$G:$G,'[1]Rincian Keluar'!$E:$E,'RIDHO 01'!C30,'[1]Rincian Keluar'!$D:$D,'RIDHO 01'!$D$1,'[1]Rincian Keluar'!$H:$H,'RIDHO 01'!$J$1,'[1]Rincian Keluar'!$F:$F,'RIDHO 01'!M30) -> 0 | F30: 100000 | G30: =E30*F30 -> 0 | M30: =$C$24 -> PINTU
B31: 7 | C31: Pengunci Pintu 2 daun | D31: =IFERROR(HLOOKUP($J$1,[1]DB!$C$1:$K$172,31,FALSE),"") -> 1 | E31: =SUMIFS('[1]Rincian Keluar'!$G:$G,'[1]Rincian Keluar'!$E:$E,'RIDHO 01'!C31,'[1]Rincian Keluar'!$D:$D,'RIDHO 01'!$D$1,'[1]Rincian Keluar'!$H:$H,'RIDHO 01'!$J$1,'[1]Rincian Keluar'!$F:$F,'RIDHO 01'!M31) -> 0 | F31: 60000 | G31: =E31*F31 -> 0 | M31: =$C$24 -> PINTU
B32: 8 | C32: Pegangan kunci 1 daun | D32: =IFERROR(HLOOKUP($J$1,[1]DB!$C$1:$K$172,32,FALSE),"") -> 3 | E32: =SUMIFS('[1]Rincian Keluar'!$G:$G,'[1]Rincian Keluar'!$E:$E,'RIDHO 01'!C32,'[1]Rincian Keluar'!$D:$D,'RIDHO 01'!$D$1,'[1]Rincian Keluar'!$H:$H,'RIDHO 01'!$J$1,'[1]Rincian Keluar'!$F:$F,'RIDHO 01'!M32) -> 0 | F32: 65000 | G32: =E32*F32 -> 0 | M32: =$C$24 -> PINTU
B33: 9 | C33: Avian | D33: =IFERROR(HLOOKUP($J$1,[1]DB!$C$1:$K$172,33,FALSE),"") -> 4 | E33: =SUMIFS('[1]Rincian Keluar'!$G:$G,'[1]Rincian Keluar'!$E:$E,'RIDHO 01'!C33,'[1]Rincian Keluar'!$D:$D,'RIDHO 01'!$D$1,'[1]Rincian Keluar'!$H:$H,'RIDHO 01'!$J$1,'[1]Rincian Keluar'!$F:$F,'RIDHO 01'!M33) -> 0 | F33: 83000 | G33: =E33*F33 -> 0 | M33: =$C$24 -> PINTU
B34: 10 | C34: Tinner Nb Kaleng | D34: =IFERROR(HLOOKUP($J$1,[1]DB!$C$1:$K$172,34,FALSE),"") -> 2 | E34: =SUMIFS('[1]Rincian Keluar'!$G:$G,'[1]Rincian Keluar'!$E:$E,'RIDHO 01'!C34,'[1]Rincian Keluar'!$D:$D,'RIDHO 01'!$D$1,'[1]Rincian Keluar'!$H:$H,'RIDHO 01'!$J$1,'[1]Rincian Keluar'!$F:$F,'RIDHO 01'!M34) -> 0 | F34: 23000 | G34: =E34*F34 -> 0 | M34: =$C$24 -> PINTU
B35: 11 | C35: Slot 6 " | D35: =IFERROR(HLOOKUP($J$1,[1]DB!$C$1:$K$172,35,FALSE),"") -> 1 | E35: =SUMIFS('[1]Rincian Keluar'!$G:$G,'[1]Rincian Keluar'!$E:$E,'RIDHO 01'!C35,'[1]Rincian Keluar'!$D:$D,'RIDHO 01'!$D$1,'[1]Rincian Keluar'!$H:$H,'RIDHO 01'!$J$1,'[1]Rincian Keluar'!$F:$F,'RIDHO 01'!M35) -> 0 | F35: 17000 | G35: =E35*F35 -> 0 | M35: =$C$24 -> PINTU
B36: 12 | C36: Slot 4" | D36: =IFERROR(HLOOKUP($J$1,[1]DB!$C$1:$K$172,36,FALSE),"") -> 1 | E36: =SUMIFS('[1]Rincian Keluar'!$G:$G,'[1]Rincian Keluar'!$E:$E,'RIDHO 01'!C36,'[1]Rincian Keluar'!$D:$D,'RIDHO 01'!$D$1,'[1]Rincian Keluar'!$H:$H,'RIDHO 01'!$J$1,'[1]Rincian Keluar'!$F:$F,'RIDHO 01'!M36) -> 0 | F36: 11000 | G36: =E36*F36 -> 0 | M36: =$C$24 -> PINTU
B37: E | C37: BATA
B38: 1 | C38: Papan | D38: =IFERROR(HLOOKUP($J$1,[1]DB!$C$1:$K$172,38,FALSE),"") -> 38 | E38: =SUMIFS('[1]Rincian Keluar'!$G:$G,'[1]Rincian Keluar'!$E:$E,'RIDHO 01'!C38,'[1]Rincian Keluar'!$D:$D,'RIDHO 01'!$D$1,'[1]Rincian Keluar'!$H:$H,'RIDHO 01'!$J$1,'[1]Rincian Keluar'!$F:$F,'RIDHO 01'!M38) -> 0 | F38: 11000 | G38: =E38*F38 -> 0 | H38: 965000 | I38: =IFERROR(VLOOKUP($C37,[1]HK!$B$5:$C$14,2,FALSE),"")*$J1 -> 5560000 | J38: =I38-H38 -> 4595000 | K38: 1 | M38: =$C$37 -> BATA
B39: 2 | C39: Kayu 3/5 | D39: =IFERROR(HLOOKUP($J$1,[1]DB!$C$1:$K$172,39,FALSE),"") -> 41 | E39: =SUMIFS('[1]Rincian Keluar'!$G:$G,'[1]Rincian Keluar'!$E:$E,'RIDHO 01'!C39,'[1]Rincian Keluar'!$D:$D,'RIDHO 01'!$D$1,'[1]Rincian Keluar'!$H:$H,'RIDHO 01'!$J$1,'[1]Rincian Keluar'!$F:$F,'RIDHO 01'!M39) -> 0 | F39: 11000 | G39: =E39*F39 -> 0 | M39: =$C$37 -> BATA
B40: 3 | C40: Besi ø6 | D40: =IFERROR(HLOOKUP($J$1,[1]DB!$C$1:$K$172,40,FALSE),"") -> 8 | E40: =SUMIFS('[1]Rincian Keluar'!$G:$G,'[1]Rincian Keluar'!$E:$E,'RIDHO 01'!C40,'[1]Rincian Keluar'!$D:$D,'RIDHO 01'!$D$1,'[1]Rincian Keluar'!$H:$H,'RIDHO 01'!$J$1,'[1]Rincian Keluar'!$F:$F,'RIDHO 01'!M40) -> 0 | F40: 22000 | G40: =E40*F40 -> 0 | M40: =$C$37 -> BATA
B41: 4 | C41: Besi ø8 | D41: =IFERROR(HLOOKUP($J$1,[1]DB!$C$1:$K$172,41,FALSE),"") -> 14 | E41: =SUMIFS('[1]Rincian Keluar'!$G:$G,'[1]Rincian Keluar'!$E:$E,'RIDHO 01'!C41,'[1]Rincian Keluar'!$D:$D,'RIDHO 01'!$D$1,'[1]Rincian Keluar'!$H:$H,'RIDHO 01'!$J$1,'[1]Rincian Keluar'!$F:$F,'RIDHO 01'!M41) -> 0 | F41: 35000 | G41: =E41*F41 -> 0 | M41: =$C$37 -> BATA
B42: 5 | C42: Besi ø6 | D42: =IFERROR(HLOOKUP($J$1,[1]DB!$C$1:$K$172,42,FALSE),"") -> 3 | E42: =SUMIFS('[1]Rincian Keluar'!$G:$G,'[1]Rincian Keluar'!$E:$E,'RIDHO 01'!C42,'[1]Rincian Keluar'!$D:$D,'RIDHO 01'!$D$1,'[1]Rincian Keluar'!$H:$H,'RIDHO 01'!$J$1,'[1]Rincian Keluar'!$F:$F,'RIDHO 01'!M42) -> 0 | F42: =F40 -> 22000 | G42: =E42*F42 -> 0 | M42: =$C$37 -> BATA
...

Sheet SUKABASUKI
B1: LOKASI | D1: SUKABASUKI | H1: TYPE | J1: 100
B4: No. | C4: URAIAN PEKERJAAN | D4: BAHAN | F4: HARGA BAHAN | G4: TOTAL HARGA | H4: UPAH | I4: BORONGAN | J4: UNTUNG/RUGI | K4: PROGRES
D5: BAKU | E5: OUT | F5: ( Rp ) | G5: ( Rp )
B6: A | C6: PONDASI
B7: 1 | C7: Besi ø6 | D7: =IFERROR(HLOOKUP($J$1,[1]DB!$C$1:$K$172,7,FALSE),"") -> 24 | E7: =SUMIFS('[1]Rincian Keluar'!$G:$G,'[1]Rincian Keluar'!$E:$E,SUKABASUKI!C7,'[1]Rincian Keluar'!$D:$D,SUKABASUKI!$D$1,'[1]Rincian Keluar'!$H:$H,SUKABASUKI!$J$1,'[1]Rincian Keluar'!$F:$F,SUKABASUKI!M7) -> 0 | F7: 21500 | G7: =E7*F7 -> 0 | H7: 3880600 | I7: =IFERROR(VLOOKUP($C6,[1]HK!$B$5:$C$14,2,FALSE),"")*$J1 -> 4170000 | J7: =I7-H7 -> 289400 | K7: 1 | M7: =$C$6 -> PONDASI
B8: 2 | C8: Besi ø8 Ulir | D8: =IFERROR(HLOOKUP($J$1,[1]DB!$C$1:$K$172,8,FALSE),"") -> 82 | E8: =SUMIFS('[1]Rincian Keluar'!$G:$G,'[1]Rincian Keluar'!$E:$E,SUKABASUKI!C8,'[1]Rincian Keluar'!$D:$D,SUKABASUKI!$D$1,'[1]Rincian Keluar'!$H:$H,SUKABASUKI!$J$1,'[1]Rincian Keluar'!$F:$F,SUKABASUKI!M8) -> 0 | F8: 49000 | G8: =E8*F8 -> 0 | M8: =$C$6 -> PONDASI
B9: 3 | C9: Kayu 3/5 | D9: =IFERROR(HLOOKUP($J$1,[1]DB!$C$1:$K$172,9,FALSE),"") -> 70 | E9: =SUMIFS('[1]Rincian Keluar'!$G:$G,'[1]Rincian Keluar'!$E:$E,SUKABASUKI!C9,'[1]Rincian Keluar'!$D:$D,SUKABASUKI!$D$1,'[1]Rincian Keluar'!$H:$H,SUKABASUKI!$J$1,'[1]Rincian Keluar'!$F:$F,SUKABASUKI!M9) -> 0 | F9: 11000 | G9: =E9*F9 -> 0 | M9: =$C$6 -> PONDASI
B10: 4 | C10: Cerucuk | D10: =IFERROR(HLOOKUP($J$1,[1]DB!$C$1:$K$172,10,FALSE),"") -> 148 | E10: =SUMIFS('[1]Rincian Keluar'!$G:$G,'[1]Rincian Keluar'!$E:$E,SUKABASUKI!C10,'[1]Rincian Keluar'!$D:$D,SUKABASUKI!$D$1,'[1]Rincian Keluar'!$H:$H,SUKABASUKI!$J$1,'[1]Rincian Keluar'!$F:$F,SUKABASUKI!M10) -> 0 | F10: 8000 | G10: =E10*F10 -> 0 | M10: =$C$6 -> PONDASI
B11: 5 | C11: Papan Mal | D11: =IFERROR(HLOOKUP($J$1,[1]DB!$C$1:$K$172,11,FALSE),"") -> 328 | E11: =SUMIFS('[1]Rincian Keluar'!$G:$G,'[1]Rincian Keluar'!$E:$E,SUKABASUKI!C11,'[1]Rincian Keluar'!$D:$D,SUKABASUKI!$D$1,'[1]Rincian Keluar'!$H:$H,SUKABASUKI!$J$1,'[1]Rincian Keluar'!$F:$F,SUKABASUKI!M11) -> 0 | F11: 11000 | G11: =E11*F11 -> 0 | M11: =$C$6 -> PONDASI
B12: 6 | C12: Pasir | D12: =IFERROR(HLOOKUP($J$1,[1]DB!$C$1:$K$172,12,FALSE),"") -> 26 | E12: =SUMIFS('[1]Rincian Keluar'!$G:$G,'[1]Rincian Keluar'!$E:$E,SUKABASUKI!C12,'[1]Rincian Keluar'!$D:$D,SUKABASUKI!$D$1,'[1]Rincian Keluar'!$H:$H,SUKABASUKI!$J$1,'[1]Rincian Keluar'!$F:$F,SUKABASUKI!M12) -> 0 | F12: 150000 | G12: =E12*F12 -> 0 | M12: =$C$6 -> PONDASI
B13: 7 | C13: Batu | D13: =IFERROR(HLOOKUP($J$1,[1]DB!$C$1:$K$172,13,FALSE),"") -> 4 | E13: =SUMIFS('[1]Rincian Keluar'!$G:$G,'[1]Rincian Keluar'!$E:$E,SUKABASUKI!C13,'[1]Rincian Keluar'!$D:$D,SUKABASUKI!$D$1,'[1]Rincian Keluar'!$H:$H,SUKABASUKI!$J$1,'[1]Rincian Keluar'!$F:$F,SUKABASUKI!M13) -> 0 | F13: 500000 | G13: =E13*F13 -> 0 | M13: =$C$6 -> PONDASI
B14: 8 | C14: Semen PCC 40 Kg Tiga Roda | D14: =IFERROR(HLOOKUP($J$1,[1]DB!$C$1:$K$172,14,FALSE),"") -> 77 | E14: =SUMIFS('[1]Rincian Keluar'!$G:$G,'[1]Rincian Keluar'!$E:$E,SUKABASUKI!C14,'[1]Rincian Keluar'!$D:$D,SUKABASUKI!$D$1,'[1]Rincian Keluar'!$H:$H,SUKABASUKI!$J$1,'[1]Rincian Keluar'!$F:$F,SUKABASUKI!M14) -> 0 | F14: 60700 | G14: =E14*F14 -> 0 | M14: =$C$6 -> PONDASI
B15: B | C15: URUG
B16: 1 | C16: Pasir | D16: =IFERROR(HLOOKUP($J$1,[1]DB!$C$1:$K$172,16,FALSE),"") -> 64 | E16: =SUMIFS('[1]Rincian Keluar'!$G:$G,'[1]Rincian Keluar'!$E:$E,SUKABASUKI!C16,'[1]Rincian Keluar'!$D:$D,SUKABASUKI!$D$1,'[1]Rincian Keluar'!$H:$H,SUKABASUKI!$J$1,'[1]Rincian Keluar'!$F:$F,SUKABASUKI!M16) -> 0 | F16: 150000 | G16: =E16*F16 -> 0 | H16: 1289600 | I16: =IFERROR(VLOOKUP($C15,[1]HK!$B$5:$C$14,2,FALSE),"")*$J1 -> 1670000 | J16: =I16-H16 -> 380400 | K16: 1 | M16: =$C$15 -> URUG
B17: 2 | C17: Pipa 4" | D17: =IFERROR(HLOOKUP($J$1,[1]DB!$C$1:$K$172,17,FALSE),"") -> 2 | E17: =SUMIFS('[1]Rincian Keluar'!$G:$G,'[1]Rincian Keluar'!$E:$E,SUKABASUKI!C17,'[1]Rincian Keluar'!$D:$D,SUKABASUKI!$D$1,'[1]Rincian Keluar'!$H:$H,SUKABASUKI!$J$1,'[1]Rincian Keluar'!$F:$F,SUKABASUKI!M17) -> 0 | F17: 133500 | G17: =E17*F17 -> 0 | M17: =$C$15 -> URUG
B18: 3 | C18: Pipa 2" | D18: =IFERROR(HLOOKUP($J$1,[1]DB!$C$1:$K$172,18,FALSE),"") -> 2 | E18: =SUMIFS('[1]Rincian Keluar'!$G:$G,'[1]Rincian Keluar'!$E:$E,SUKABASUKI!C18,'[1]Rincian Keluar'!$D:$D,SUKABASUKI!$D$1,'[1]Rincian Keluar'!$H:$H,SUKABASUKI!$J$1,'[1]Rincian Keluar'!$F:$F,SUKABASUKI!M18) -> 0 | F18: 48000 | G18: =E18*F18 -> 0 | M18: =$C$15 -> URUG
B19: C | C19: COR LANTAI
B20: 1 | C20: Besi ø6 | D20: =IFERROR(HLOOKUP($J$1,[1]DB!$C$1:$K$172,20,FALSE),"") -> 31 | E20: =SUMIFS('[1]Rincian Keluar'!$G:$G,'[1]Rincian Keluar'!$E:$E,SUKABASUKI!C20,'[1]Rincian Keluar'!$D:$D,SUKABASUKI!$D$1,'[1]Rincian Keluar'!$H:$H,SUKABASUKI!$J$1,'[1]Rincian Keluar'!$F:$F,SUKABASUKI!M20) -> 44 | F20: 22000 | G20: =E20*F20 -> 968000 | H20: 1372800 | I20: =IFERROR(VLOOKUP($C19,[1]HK!$B$5:$C$14,2,FALSE),"")*$J1 -> 1000000 | J20: =I20-H20 -> -372800 | K20: 1 | M20: =$C$19 -> COR LANTAI
B21: 2 | C21: Pasir | D21: =IFERROR(HLOOKUP($J$1,[1]DB!$C$1:$K$172,21,FALSE),"") -> 10 | E21: =SUMIFS('[1]Rincian Keluar'!$G:$G,'[1]Rincian Keluar'!$E:$E,SUKABASUKI!C21,'[1]Rincian Keluar'!$D:$D,SUKABASUKI!$D$1,'[1]Rincian Keluar'!$H:$H,SUKABASUKI!$J$1,'[1]Rincian Keluar'!$F:$F,SUKABASUKI!M21) -> 10 | F21: 150000 | G21: =E21*F21 -> 1500000 | M21: =$C$19 -> COR LANTAI
B22: 3 | C22: Semen PCC 40 Kg Tiga Roda | D22: =IFERROR(HLOOKUP($J$1,[1]DB!$C$1:$K$172,22,FALSE),"") -> 28 | E22: =SUMIFS('[1]Rincian Keluar'!$G:$G,'[1]Rincian Keluar'!$E:$E,SUKABASUKI!C22,'[1]Rincian Keluar'!$D:$D,SUKABASUKI!$D$1,'[1]Rincian Keluar'!$H:$H,SUKABASUKI!$J$1,'[1]Rincian Keluar'!$F:$F,SUKABASUKI!M22) -> 27 | F22: 60700 | G22: =E22*F22 -> 1638900 | M22: =$C$19 -> COR LANTAI
B23: 4 | C23: Plastik cor | D23: =IFERROR(HLOOKUP($J$1,[1]DB!$C$1:$K$172,23,FALSE),"") -> 13 | E23: =SUMIFS('[1]Rincian Keluar'!$G:$G,'[1]Rincian Keluar'!$E:$E,SUKABASUKI!C23,'[1]Rincian Keluar'!$D:$D,SUKABASUKI!$D$1,'[1]Rincian Keluar'!$H:$H,SUKABASUKI!$J$1,'[1]Rincian Keluar'!$F:$F,SUKABASUKI!M23) -> 13 | F23: 15000 | G23: =E23*F23 -> 195000 | M23: =$C$19 -> COR LANTAI
B24: D | C24: PINTU
B25: 1 | C25: Pintu Kayu 120 x 220 | D25: =IFERROR(HLOOKUP($J$1,[1]DB!$C$1:$K$172,25,FALSE),"") -> 1 | E25: =SUMIFS('[1]Rincian Keluar'!$G:$G,'[1]Rincian Keluar'!$E:$E,SUKABASUKI!C25,'[1]Rincian Keluar'!$D:$D,SUKABASUKI!$D$1,'[1]Rincian Keluar'!$H:$H,SUKABASUKI!$J$1,'[1]Rincian Keluar'!$F:$F,SUKABASUKI!M25) -> 0 | F25: 1550000 | G25: =E25*F25 -> 0 | I25: =IFERROR(VLOOKUP($C24,[1]HK!$B$5:$C$14,2,FALSE),"")*$J1 -> #VALUE! | M25: =$C$24 -> PINTU
B26: 2 | C26: Pintu Kayu 80 x 220 | D26: =IFERROR(HLOOKUP($J$1,[1]DB!$C$1:$K$172,26,FALSE),"") -> 3 | E26: =SUMIFS('[1]Rincian Keluar'!$G:$G,'[1]Rincian Keluar'!$E:$E,SUKABASUKI!C26,'[1]Rincian Keluar'!$D:$D,SUKABASUKI!$D$1,'[1]Rincian Keluar'!$H:$H,SUKABASUKI!$J$1,'[1]Rincian Keluar'!$F:$F,SUKABASUKI!M26) -> 0 | F26: 775000 | G26: =E26*F26 -> 0 | M26: =$C$24 -> PINTU
B27: 3 | C27: Pintu WC PVC Biru | D27: =IFERROR(HLOOKUP($J$1,[1]DB!$C$1:$K$172,27,FALSE),"") -> 2 | E27: =SUMIFS('[1]Rincian Keluar'!$G:$G,'[1]Rincian Keluar'!$E:$E,SUKABASUKI!C27,'[1]Rincian Keluar'!$D:$D,SUKABASUKI!$D$1,'[1]Rincian Keluar'!$H:$H,SUKABASUKI!$J$1,'[1]Rincian Keluar'!$F:$F,SUKABASUKI!M27) -> 0 | F27: 260000 | G27: =E27*F27 -> 0 | M27: =$C$24 -> PINTU
B28: 4 | C28: Pintu WC Edenjoice Putih | D28: =IFERROR(HLOOKUP($J$1,[1]DB!$C$1:$K$172,28,FALSE),"") -> 1 | E28: =SUMIFS('[1]Rincian Keluar'!$G:$G,'[1]Rincian Keluar'!$E:$E,SUKABASUKI!C28,'[1]Rincian Keluar'!$D:$D,SUKABASUKI!$D$1,'[1]Rincian Keluar'!$H:$H,SUKABASUKI!$J$1,'[1]Rincian Keluar'!$F:$F,SUKABASUKI!M28) -> 0 | F28: 799000 | G28: =E28*F28 -> 0 | M28: =$C$24 -> PINTU
B29: 5 | C29: Engsel Pintu 4" | D29: =IFERROR(HLOOKUP($J$1,[1]DB!$C$1:$K$172,29,FALSE),"") -> 15 | E29: =SUMIFS('[1]Rincian Keluar'!$G:$G,'[1]Rincian Keluar'!$E:$E,SUKABASUKI!C29,'[1]Rincian Keluar'!$D:$D,SUKABASUKI!$D$1,'[1]Rincian Keluar'!$H:$H,SUKABASUKI!$J$1,'[1]Rincian Keluar'!$F:$F,SUKABASUKI!M29) -> 0 | F29: 15000 | G29: =E29*F29 -> 0 | M29: =$C$24 -> PINTU
B30: 6 | C30: Peganggan pintu 2 daun | D30: =IFERROR(HLOOKUP($J$1,[1]DB!$C$1:$K$172,30,FALSE),"") -> 2 | E30: =SUMIFS('[1]Rincian Keluar'!$G:$G,'[1]Rincian Keluar'!$E:$E,SUKABASUKI!C30,'[1]Rincian Keluar'!$D:$D,SUKABASUKI!$D$1,'[1]Rincian Keluar'!$H:$H,SUKABASUKI!$J$1,'[1]Rincian Keluar'!$F:$F,SUKABASUKI!M30) -> 0 | F30: 100000 | G30: =E30*F30 -> 0 | M30: =$C$24 -> PINTU
B31: 7 | C31: Pengunci Pintu 2 daun | D31: =IFERROR(HLOOKUP($J$1,[1]DB!$C$1:$K$172,31,FALSE),"") -> 1 | E31: =SUMIFS('[1]Rincian Keluar'!$G:$G,'[1]Rincian Keluar'!$E:$E,SUKABASUKI!C31,'[1]Rincian Keluar'!$D:$D,SUKABASUKI!$D$1,'[1]Rincian Keluar'!$H:$H,SUKABASUKI!$J$1,'[1]Rincian Keluar'!$F:$F,SUKABASUKI!M31) -> 0 | F31: 60000 | G31: =E31*F31 -> 0 | M31: =$C$24 -> PINTU
B32: 8 | C32: Pegangan kunci 1 daun | D32: =IFERROR(HLOOKUP($J$1,[1]DB!$C$1:$K$172,32,FALSE),"") -> 3 | E32: =SUMIFS('[1]Rincian Keluar'!$G:$G,'[1]Rincian Keluar'!$E:$E,SUKABASUKI!C32,'[1]Rincian Keluar'!$D:$D,SUKABASUKI!$D$1,'[1]Rincian Keluar'!$H:$H,SUKABASUKI!$J$1,'[1]Rincian Keluar'!$F:$F,SUKABASUKI!M32) -> 0 | F32: 65000 | G32: =E32*F32 -> 0 | M32: =$C$24 -> PINTU
B33: 9 | C33: Avian | D33: =IFERROR(HLOOKUP($J$1,[1]DB!$C$1:$K$172,33,FALSE),"") -> 4 | E33: =SUMIFS('[1]Rincian Keluar'!$G:$G,'[1]Rincian Keluar'!$E:$E,SUKABASUKI!C33,'[1]Rincian Keluar'!$D:$D,SUKABASUKI!$D$1,'[1]Rincian Keluar'!$H:$H,SUKABASUKI!$J$1,'[1]Rincian Keluar'!$F:$F,SUKABASUKI!M33) -> 0 | F33: 83000 | G33: =E33*F33 -> 0 | M33: =$C$24 -> PINTU
B34: 10 | C34: Tinner Nb Kaleng | D34: =IFERROR(HLOOKUP($J$1,[1]DB!$C$1:$K$172,34,FALSE),"") -> 2 | E34: =SUMIFS('[1]Rincian Keluar'!$G:$G,'[1]Rincian Keluar'!$E:$E,SUKABASUKI!C34,'[1]Rincian Keluar'!$D:$D,SUKABASUKI!$D$1,'[1]Rincian Keluar'!$H:$H,SUKABASUKI!$J$1,'[1]Rincian Keluar'!$F:$F,SUKABASUKI!M34) -> 0 | F34: 23000 | G34: =E34*F34 -> 0 | M34: =$C$24 -> PINTU
B35: 11 | C35: Slot 6 " | D35: =IFERROR(HLOOKUP($J$1,[1]DB!$C$1:$K$172,35,FALSE),"") -> 1 | E35: =SUMIFS('[1]Rincian Keluar'!$G:$G,'[1]Rincian Keluar'!$E:$E,SUKABASUKI!C35,'[1]Rincian Keluar'!$D:$D,SUKABASUKI!$D$1,'[1]Rincian Keluar'!$H:$H,SUKABASUKI!$J$1,'[1]Rincian Keluar'!$F:$F,SUKABASUKI!M35) -> 0 | F35: 17000 | G35: =E35*F35 -> 0 | M35: =$C$24 -> PINTU
B36: 12 | C36: Slot 4" | D36: =IFERROR(HLOOKUP($J$1,[1]DB!$C$1:$K$172,36,FALSE),"") -> 1 | E36: =SUMIFS('[1]Rincian Keluar'!$G:$G,'[1]Rincian Keluar'!$E:$E,SUKABASUKI!C36,'[1]Rincian Keluar'!$D:$D,SUKABASUKI!$D$1,'[1]Rincian Keluar'!$H:$H,SUKABASUKI!$J$1,'[1]Rincian Keluar'!$F:$F,SUKABASUKI!M36) -> 0 | F36: 11000 | G36: =E36*F36 -> 0 | M36: =$C$24 -> PINTU
B37: E | C37: BATA
B38: 1 | C38: Papan | D38: =IFERROR(HLOOKUP($J$1,[1]DB!$C$1:$K$172,38,FALSE),"") -> 48 | E38: =SUMIFS('[1]Rincian Keluar'!$G:$G,'[1]Rincian Keluar'!$E:$E,SUKABASUKI!C38,'[1]Rincian Keluar'!$D:$D,SUKABASUKI!$D$1,'[1]Rincian Keluar'!$H:$H,SUKABASUKI!$J$1,'[1]Rincian Keluar'!$F:$F,SUKABASUKI!M38) -> 18 | F38: 11000 | G38: =E38*F38 -> 198000 | H38: 6780000 | I38: =IFERROR(VLOOKUP($C37,[1]HK!$B$5:$C$14,2,FALSE),"")*$J1 -> 6950000 | J38: =I38-H38 -> 170000 | K38: 1 | M38: =$C$37 -> BATA
B39: 2 | C39: Kayu 3/5 | D39: =IFERROR(HLOOKUP($J$1,[1]DB!$C$1:$K$172,39,FALSE),"") -> 51 | E39: =SUMIFS('[1]Rincian Keluar'!$G:$G,'[1]Rincian Keluar'!$E:$E,SUKABASUKI!C39,'[1]Rincian Keluar'!$D:$D,SUKABASUKI!$D$1,'[1]Rincian Keluar'!$H:$H,SUKABASUKI!$J$1,'[1]Rincian Keluar'!$F:$F,SUKABASUKI!M39) -> 18 | F39: 11000 | G39: =E39*F39 -> 198000 | M39: =$C$37 -> BATA
B40: 3 | C40: Besi ø6 | D40: =IFERROR(HLOOKUP($J$1,[1]DB!$C$1:$K$172,40,FALSE),"") -> 10 | E40: =SUMIFS('[1]Rincian Keluar'!$G:$G,'[1]Rincian Keluar'!$E:$E,SUKABASUKI!C40,'[1]Rincian Keluar'!$D:$D,SUKABASUKI!$D$1,'[1]Rincian Keluar'!$H:$H,SUKABASUKI!$J$1,'[1]Rincian Keluar'!$F:$F,SUKABASUKI!M40) -> 2 | F40: 22000 | G40: =E40*F40 -> 44000 | M40: =$C$37 -> BATA
B41: 4 | C41: Besi ø8 | D41: =IFERROR(HLOOKUP($J$1,[1]DB!$C$1:$K$172,41,FALSE),"") -> 17 | E41: =SUMIFS('[1]Rincian Keluar'!$G:$G,'[1]Rincian Keluar'!$E:$E,SUKABASUKI!C41,'[1]Rincian Keluar'!$D:$D,SUKABASUKI!$D$1,'[1]Rincian Keluar'!$H:$H,SUKABASUKI!$J$1,'[1]Rincian Keluar'!$F:$F,SUKABASUKI!M41) -> 16 | F41: 35000 | G41: =E41*F41 -> 560000 | M41: =$C$37 -> BATA
B42: 5 | C42: Besi ø6 | D42: =IFERROR(HLOOKUP($J$1,[1]DB!$C$1:$K$172,42,FALSE),"") -> 4 | E42: =SUMIFS('[1]Rincian Keluar'!$G:$G,'[1]Rincian Keluar'!$E:$E,SUKABASUKI!C42,'[1]Rincian Keluar'!$D:$D,SUKABASUKI!$D$1,'[1]Rincian Keluar'!$H:$H,SUKABASUKI!$J$1,'[1]Rincian Keluar'!$F:$F,SUKABASUKI!M42) -> 0 | F42: =F40 -> 22000 | G42: =E42*F42 -> 0 | M42: =$C$37 -> BATA
...

Sheet PELANGI 04
B1: LOKASI | D1: PELANGI 04 | H1: TYPE | J1: 55
B4: No. | C4: URAIAN PEKERJAAN | D4: BAHAN | F4: HARGA BAHAN | G4: TOTAL HARGA | H4: UPAH | I4: BORONGAN | J4: UNTUNG/RUGI | K4: PROGRES
D5: BAKU | E5: OUT | F5: ( Rp ) | G5: ( Rp )
B6: A | C6: PONDASI
B7: 1 | C7: Besi ø6 | D7: =IFERROR(HLOOKUP($J$1,[1]DB!$C$1:$K$172,7,FALSE),"") -> 13 | E7: =SUMIFS('[1]Rincian Keluar'!$G:$G,'[1]Rincian Keluar'!$E:$E,'PELANGI 04'!C7,'[1]Rincian Keluar'!$D:$D,'PELANGI 04'!$D$1,'[1]Rincian Keluar'!$H:$H,'PELANGI 04'!$J$1,'[1]Rincian Keluar'!$F:$F,'PELANGI 04'!M7) -> 10 | F7: 21500 | G7: =E7*F7 -> 215000 | H7: 2157000 | I7: =IFERROR(VLOOKUP($C6,[1]HK!$B$5:$C$14,2,FALSE),"")*$J1 -> 2293500 | J7: =I7-H7 -> 136500 | K7: 1 | M7: =$C$6 -> PONDASI
B8: 2 | C8: Besi ø8 Ulir | D8: =IFERROR(HLOOKUP($J$1,[1]DB!$C$1:$K$172,8,FALSE),"") -> 45 | E8: =SUMIFS('[1]Rincian Keluar'!$G:$G,'[1]Rincian Keluar'!$E:$E,'PELANGI 04'!C8,'[1]Rincian Keluar'!$D:$D,'PELANGI 04'!$D$1,'[1]Rincian Keluar'!$H:$H,'PELANGI 04'!$J$1,'[1]Rincian Keluar'!$F:$F,'PELANGI 04'!M8) -> 35 | F8: 49000 | G8: =E8*F8 -> 1715000 | M8: =$C$6 -> PONDASI
B9: 3 | C9: Kayu 3/5 | D9: =IFERROR(HLOOKUP($J$1,[1]DB!$C$1:$K$172,9,FALSE),"") -> 38 | E9: =SUMIFS('[1]Rincian Keluar'!$G:$G,'[1]Rincian Keluar'!$E:$E,'PELANGI 04'!C9,'[1]Rincian Keluar'!$D:$D,'PELANGI 04'!$D$1,'[1]Rincian Keluar'!$H:$H,'PELANGI 04'!$J$1,'[1]Rincian Keluar'!$F:$F,'PELANGI 04'!M9) -> 12 | F9: 11000 | G9: =E9*F9 -> 132000 | M9: =$C$6 -> PONDASI
B10: 4 | C10: Cerucuk | D10: =IFERROR(HLOOKUP($J$1,[1]DB!$C$1:$K$172,10,FALSE),"") -> 81 | E10: =SUMIFS('[1]Rincian Keluar'!$G:$G,'[1]Rincian Keluar'!$E:$E,'PELANGI 04'!C10,'[1]Rincian Keluar'!$D:$D,'PELANGI 04'!$D$1,'[1]Rincian Keluar'!$H:$H,'PELANGI 04'!$J$1,'[1]Rincian Keluar'!$F:$F,'PELANGI 04'!M10) -> 71 | F10: 8000 | G10: =E10*F10 -> 568000 | M10: =$C$6 -> PONDASI
B11: 5 | C11: Papan Mal | D11: =IFERROR(HLOOKUP($J$1,[1]DB!$C$1:$K$172,11,FALSE),"") -> 180 | E11: =SUMIFS('[1]Rincian Keluar'!$G:$G,'[1]Rincian Keluar'!$E:$E,'PELANGI 04'!C11,'[1]Rincian Keluar'!$D:$D,'PELANGI 04'!$D$1,'[1]Rincian Keluar'!$H:$H,'PELANGI 04'!$J$1,'[1]Rincian Keluar'!$F:$F,'PELANGI 04'!M11) -> 0 | F11: 11000 | G11: =E11*F11 -> 0 | M11: =$C$6 -> PONDASI
B12: 6 | C12: Pasir | D12: =IFERROR(HLOOKUP($J$1,[1]DB!$C$1:$K$172,12,FALSE),"") -> 14 | E12: =SUMIFS('[1]Rincian Keluar'!$G:$G,'[1]Rincian Keluar'!$E:$E,'PELANGI 04'!C12,'[1]Rincian Keluar'!$D:$D,'PELANGI 04'!$D$1,'[1]Rincian Keluar'!$H:$H,'PELANGI 04'!$J$1,'[1]Rincian Keluar'!$F:$F,'PELANGI 04'!M12) -> 12 | F12: 150000 | G12: =E12*F12 -> 1800000 | M12: =$C$6 -> PONDASI
B13: 7 | C13: Batu | D13: =IFERROR(HLOOKUP($J$1,[1]DB!$C$1:$K$172,13,FALSE),"") -> 2 | E13: =SUMIFS('[1]Rincian Keluar'!$G:$G,'[1]Rincian Keluar'!$E:$E,'PELANGI 04'!C13,'[1]Rincian Keluar'!$D:$D,'PELANGI 04'!$D$1,'[1]Rincian Keluar'!$H:$H,'PELANGI 04'!$J$1,'[1]Rincian Keluar'!$F:$F,'PELANGI 04'!M13) -> 1 | F13: 500000 | G13: =E13*F13 -> 500000 | M13: =$C$6 -> PONDASI
B14: 8 | C14: Semen PCC 40 Kg Tiga Roda | D14: =IFERROR(HLOOKUP($J$1,[1]DB!$C$1:$K$172,14,FALSE),"") -> 42 | E14: =SUMIFS('[1]Rincian Keluar'!$G:$G,'[1]Rincian Keluar'!$E:$E,'PELANGI 04'!C14,'[1]Rincian Keluar'!$D:$D,'PELANGI 04'!$D$1,'[1]Rincian Keluar'!$H:$H,'PELANGI 04'!$J$1,'[1]Rincian Keluar'!$F:$F,'PELANGI 04'!M14) -> 45 | F14: 60700 | G14: =E14*F14 -> 2731500 | M14: =$C$6 -> PONDASI
B15: B | C15: URUG
B16: 1 | C16: Pasir | D16: =IFERROR(HLOOKUP($J$1,[1]DB!$C$1:$K$172,16,FALSE),"") -> 35 | E16: =SUMIFS('[1]Rincian Keluar'!$G:$G,'[1]Rincian Keluar'!$E:$E,'PELANGI 04'!C16,'[1]Rincian Keluar'!$D:$D,'PELANGI 04'!$D$1,'[1]Rincian Keluar'!$H:$H,'PELANGI 04'!$J$1,'[1]Rincian Keluar'!$F:$F,'PELANGI 04'!M16) -> 0 | F16: 150000 | G16: =E16*F16 -> 0 | I16: =IFERROR(VLOOKUP($C15,[1]HK!$B$5:$C$14,2,FALSE),"")*$J1 -> 918500 | M16: =$C$15 -> URUG
B17: 2 | C17: Pipa 4" | D17: =IFERROR(HLOOKUP($J$1,[1]DB!$C$1:$K$172,17,FALSE),"") -> 2 | E17: =SUMIFS('[1]Rincian Keluar'!$G:$G,'[1]Rincian Keluar'!$E:$E,'PELANGI 04'!C17,'[1]Rincian Keluar'!$D:$D,'PELANGI 04'!$D$1,'[1]Rincian Keluar'!$H:$H,'PELANGI 04'!$J$1,'[1]Rincian Keluar'!$F:$F,'PELANGI 04'!M17) -> 0 | F17: 133500 | G17: =E17*F17 -> 0 | M17: =$C$15 -> URUG
B18: 3 | C18: Pipa 2" | D18: =IFERROR(HLOOKUP($J$1,[1]DB!$C$1:$K$172,18,FALSE),"") -> 2 | E18: =SUMIFS('[1]Rincian Keluar'!$G:$G,'[1]Rincian Keluar'!$E:$E,'PELANGI 04'!C18,'[1]Rincian Keluar'!$D:$D,'PELANGI 04'!$D$1,'[1]Rincian Keluar'!$H:$H,'PELANGI 04'!$J$1,'[1]Rincian Keluar'!$F:$F,'PELANGI 04'!M18) -> 0 | F18: 48000 | G18: =E18*F18 -> 0 | M18: =$C$15 -> URUG
B19: C | C19: COR LANTAI
B20: 1 | C20: Besi ø6 | D20: =IFERROR(HLOOKUP($J$1,[1]DB!$C$1:$K$172,20,FALSE),"") -> 17 | E20: =SUMIFS('[1]Rincian Keluar'!$G:$G,'[1]Rincian Keluar'!$E:$E,'PELANGI 04'!C20,'[1]Rincian Keluar'!$D:$D,'PELANGI 04'!$D$1,'[1]Rincian Keluar'!$H:$H,'PELANGI 04'!$J$1,'[1]Rincian Keluar'!$F:$F,'PELANGI 04'!M20) -> 0 | F20: 22000 | G20: =E20*F20 -> 0 | I20: =IFERROR(VLOOKUP($C19,[1]HK!$B$5:$C$14,2,FALSE),"")*$J1 -> 550000 | M20: =$C$19 -> COR LANTAI
B21: 2 | C21: Pasir | D21: =IFERROR(HLOOKUP($J$1,[1]DB!$C$1:$K$172,21,FALSE),"") -> 5 | E21: =SUMIFS('[1]Rincian Keluar'!$G:$G,'[1]Rincian Keluar'!$E:$E,'PELANGI 04'!C21,'[1]Rincian Keluar'!$D:$D,'PELANGI 04'!$D$1,'[1]Rincian Keluar'!$H:$H,'PELANGI 04'!$J$1,'[1]Rincian Keluar'!$F:$F,'PELANGI 04'!M21) -> 0 | F21: 150000 | G21: =E21*F21 -> 0 | M21: =$C$19 -> COR LANTAI
B22: 3 | C22: Semen PCC 40 Kg Tiga Roda | D22: =IFERROR(HLOOKUP($J$1,[1]DB!$C$1:$K$172,22,FALSE),"") -> 15 | E22: =SUMIFS('[1]Rincian Keluar'!$G:$G,'[1]Rincian Keluar'!$E:$E,'PELANGI 04'!C22,'[1]Rincian Keluar'!$D:$D,'PELANGI 04'!$D$1,'[1]Rincian Keluar'!$H:$H,'PELANGI 04'!$J$1,'[1]Rincian Keluar'!$F:$F,'PELANGI 04'!M22) -> 0 | F22: 60700 | G22: =E22*F22 -> 0 | M22: =$C$19 -> COR LANTAI
B23: 4 | C23: Plastik cor | D23: =IFERROR(HLOOKUP($J$1,[1]DB!$C$1:$K$172,23,FALSE),"") -> 7 | E23: =SUMIFS('[1]Rincian Keluar'!$G:$G,'[1]Rincian Keluar'!$E:$E,'PELANGI 04'!C23,'[1]Rincian Keluar'!$D:$D,'PELANGI 04'!$D$1,'[1]Rincian Keluar'!$H:$H,'PELANGI 04'!$J$1,'[1]Rincian Keluar'!$F:$F,'PELANGI 04'!M23) -> 0 | F23: 15000 | G23: =E23*F23 -> 0 | M23: =$C$19 -> COR LANTAI
B24: D | C24: PINTU
B25: 1 | C25: Pintu Kayu 120 x 220 | D25: =IFERROR(HLOOKUP($J$1,[1]DB!$C$1:$K$172,25,FALSE),"") -> 1 | E25: =SUMIFS('[1]Rincian Keluar'!$G:$G,'[1]Rincian Keluar'!$E:$E,'PELANGI 04'!C25,'[1]Rincian Keluar'!$D:$D,'PELANGI 04'!$D$1,'[1]Rincian Keluar'!$H:$H,'PELANGI 04'!$J$1,'[1]Rincian Keluar'!$F:$F,'PELANGI 04'!M25) -> 0 | F25: 1550000 | G25: =E25*F25 -> 0 | I25: =IFERROR(VLOOKUP($C24,[1]HK!$B$5:$C$14,2,FALSE),"")*$J1 -> #VALUE! | M25: =$C$24 -> PINTU
B26: 2 | C26: Pintu Kayu 80 x 220 | D26: =IFERROR(HLOOKUP($J$1,[1]DB!$C$1:$K$172,26,FALSE),"") -> 3 | E26: =SUMIFS('[1]Rincian Keluar'!$G:$G,'[1]Rincian Keluar'!$E:$E,'PELANGI 04'!C26,'[1]Rincian Keluar'!$D:$D,'PELANGI 04'!$D$1,'[1]Rincian Keluar'!$H:$H,'PELANGI 04'!$J$1,'[1]Rincian Keluar'!$F:$F,'PELANGI 04'!M26) -> 0 | F26: 775000 | G26: =E26*F26 -> 0 | M26: =$C$24 -> PINTU
B27: 3 | C27: Pintu WC PVC Biru | D27: =IFERROR(HLOOKUP($J$1,[1]DB!$C$1:$K$172,27,FALSE),"") -> 2 | E27: =SUMIFS('[1]Rincian Keluar'!$G:$G,'[1]Rincian Keluar'!$E:$E,'PELANGI 04'!C27,'[1]Rincian Keluar'!$D:$D,'PELANGI 04'!$D$1,'[1]Rincian Keluar'!$H:$H,'PELANGI 04'!$J$1,'[1]Rincian Keluar'!$F:$F,'PELANGI 04'!M27) -> 0 | F27: 260000 | G27: =E27*F27 -> 0 | M27: =$C$24 -> PINTU
B28: 4 | C28: Pintu WC Edenjoice Putih | D28: =IFERROR(HLOOKUP($J$1,[1]DB!$C$1:$K$172,28,FALSE),"") -> 1 | E28: =SUMIFS('[1]Rincian Keluar'!$G:$G,'[1]Rincian Keluar'!$E:$E,'PELANGI 04'!C28,'[1]Rincian Keluar'!$D:$D,'PELANGI 04'!$D$1,'[1]Rincian Keluar'!$H:$H,'PELANGI 04'!$J$1,'[1]Rincian Keluar'!$F:$F,'PELANGI 04'!M28) -> 0 | F28: 799000 | G28: =E28*F28 -> 0 | M28: =$C$24 -> PINTU
B29: 5 | C29: Engsel Pintu 4" | D29: =IFERROR(HLOOKUP($J$1,[1]DB!$C$1:$K$172,29,FALSE),"") -> 15 | E29: =SUMIFS('[1]Rincian Keluar'!$G:$G,'[1]Rincian Keluar'!$E:$E,'PELANGI 04'!C29,'[1]Rincian Keluar'!$D:$D,'PELANGI 04'!$D$1,'[1]Rincian Keluar'!$H:$H,'PELANGI 04'!$J$1,'[1]Rincian Keluar'!$F:$F,'PELANGI 04'!M29) -> 0 | F29: 15000 | G29: =E29*F29 -> 0 | M29: =$C$24 -> PINTU
B30: 6 | C30: Peganggan pintu 2 daun | D30: =IFERROR(HLOOKUP($J$1,[1]DB!$C$1:$K$172,30,FALSE),"") -> 2 | E30: =SUMIFS('[1]Rincian Keluar'!$G:$G,'[1]Rincian Keluar'!$E:$E,'PELANGI 04'!C30,'[1]Rincian Keluar'!$D:$D,'PELANGI 04'!$D$1,'[1]Rincian Keluar'!$H:$H,'PELANGI 04'!$J$1,'[1]Rincian Keluar'!$F:$F,'PELANGI 04'!M30) -> 0 | F30: 100000 | G30: =E30*F30 -> 0 | M30: =$C$24 -> PINTU
B31: 7 | C31: Pengunci Pintu 2 daun | D31: =IFERROR(HLOOKUP($J$1,[1]DB!$C$1:$K$172,31,FALSE),"") -> 1 | E31: =SUMIFS('[1]Rincian Keluar'!$G:$G,'[1]Rincian Keluar'!$E:$E,'PELANGI 04'!C31,'[1]Rincian Keluar'!$D:$D,'PELANGI 04'!$D$1,'[1]Rincian Keluar'!$H:$H,'PELANGI 04'!$J$1,'[1]Rincian Keluar'!$F:$F,'PELANGI 04'!M31) -> 0 | F31: 60000 | G31: =E31*F31 -> 0 | M31: =$C$24 -> PINTU
B32: 8 | C32: Pegangan kunci 1 daun | D32: =IFERROR(HLOOKUP($J$1,[1]DB!$C$1:$K$172,32,FALSE),"") -> 3 | E32: =SUMIFS('[1]Rincian Keluar'!$G:$G,'[1]Rincian Keluar'!$E:$E,'PELANGI 04'!C32,'[1]Rincian Keluar'!$D:$D,'PELANGI 04'!$D$1,'[1]Rincian Keluar'!$H:$H,'PELANGI 04'!$J$1,'[1]Rincian Keluar'!$F:$F,'PELANGI 04'!M32) -> 0 | F32: 65000 | G32: =E32*F32 -> 0 | M32: =$C$24 -> PINTU
B33: 9 | C33: Avian | D33: =IFERROR(HLOOKUP($J$1,[1]DB!$C$1:$K$172,33,FALSE),"") -> 4 | E33: =SUMIFS('[1]Rincian Keluar'!$G:$G,'[1]Rincian Keluar'!$E:$E,'PELANGI 04'!C33,'[1]Rincian Keluar'!$D:$D,'PELANGI 04'!$D$1,'[1]Rincian Keluar'!$H:$H,'PELANGI 04'!$J$1,'[1]Rincian Keluar'!$F:$F,'PELANGI 04'!M33) -> 0 | F33: 83000 | G33: =E33*F33 -> 0 | M33: =$C$24 -> PINTU
B34: 10 | C34: Tinner Nb Kaleng | D34: =IFERROR(HLOOKUP($J$1,[1]DB!$C$1:$K$172,34,FALSE),"") -> 2 | E34: =SUMIFS('[1]Rincian Keluar'!$G:$G,'[1]Rincian Keluar'!$E:$E,'PELANGI 04'!C34,'[1]Rincian Keluar'!$D:$D,'PELANGI 04'!$D$1,'[1]Rincian Keluar'!$H:$H,'PELANGI 04'!$J$1,'[1]Rincian Keluar'!$F:$F,'PELANGI 04'!M34) -> 0 | F34: 23000 | G34: =E34*F34 -> 0 | M34: =$C$24 -> PINTU
B35: 11 | C35: Slot 6 " | D35: =IFERROR(HLOOKUP($J$1,[1]DB!$C$1:$K$172,35,FALSE),"") -> 1 | E35: =SUMIFS('[1]Rincian Keluar'!$G:$G,'[1]Rincian Keluar'!$E:$E,'PELANGI 04'!C35,'[1]Rincian Keluar'!$D:$D,'PELANGI 04'!$D$1,'[1]Rincian Keluar'!$H:$H,'PELANGI 04'!$J$1,'[1]Rincian Keluar'!$F:$F,'PELANGI 04'!M35) -> 0 | F35: 17000 | G35: =E35*F35 -> 0 | M35: =$C$24 -> PINTU
B36: 12 | C36: Slot 4" | D36: =IFERROR(HLOOKUP($J$1,[1]DB!$C$1:$K$172,36,FALSE),"") -> 1 | E36: =SUMIFS('[1]Rincian Keluar'!$G:$G,'[1]Rincian Keluar'!$E:$E,'PELANGI 04'!C36,'[1]Rincian Keluar'!$D:$D,'PELANGI 04'!$D$1,'[1]Rincian Keluar'!$H:$H,'PELANGI 04'!$J$1,'[1]Rincian Keluar'!$F:$F,'PELANGI 04'!M36) -> 0 | F36: 11000 | G36: =E36*F36 -> 0 | M36: =$C$24 -> PINTU
B37: E | C37: BATA
B38: 1 | C38: Papan | D38: =IFERROR(HLOOKUP($J$1,[1]DB!$C$1:$K$172,38,FALSE),"") -> 26 | E38: =SUMIFS('[1]Rincian Keluar'!$G:$G,'[1]Rincian Keluar'!$E:$E,'PELANGI 04'!C38,'[1]Rincian Keluar'!$D:$D,'PELANGI 04'!$D$1,'[1]Rincian Keluar'!$H:$H,'PELANGI 04'!$J$1,'[1]Rincian Keluar'!$F:$F,'PELANGI 04'!M38) -> 0 | F38: 11000 | G38: =E38*F38 -> 0 | I38: =IFERROR(VLOOKUP($C37,[1]HK!$B$5:$C$14,2,FALSE),"")*$J1 -> 3822500 | M38: =$C$37 -> BATA
B39: 2 | C39: Kayu 3/5 | D39: =IFERROR(HLOOKUP($J$1,[1]DB!$C$1:$K$172,39,FALSE),"") -> 28 | E39: =SUMIFS('[1]Rincian Keluar'!$G:$G,'[1]Rincian Keluar'!$E:$E,'PELANGI 04'!C39,'[1]Rincian Keluar'!$D:$D,'PELANGI 04'!$D$1,'[1]Rincian Keluar'!$H:$H,'PELANGI 04'!$J$1,'[1]Rincian Keluar'!$F:$F,'PELANGI 04'!M39) -> 0 | F39: 11000 | G39: =E39*F39 -> 0 | M39: =$C$37 -> BATA
B40: 3 | C40: Besi ø6 | D40: =IFERROR(HLOOKUP($J$1,[1]DB!$C$1:$K$172,40,FALSE),"") -> 5 | E40: =SUMIFS('[1]Rincian Keluar'!$G:$G,'[1]Rincian Keluar'!$E:$E,'PELANGI 04'!C40,'[1]Rincian Keluar'!$D:$D,'PELANGI 04'!$D$1,'[1]Rincian Keluar'!$H:$H,'PELANGI 04'!$J$1,'[1]Rincian Keluar'!$F:$F,'PELANGI 04'!M40) -> 0 | F40: 22000 | G40: =E40*F40 -> 0 | M40: =$C$37 -> BATA
B41: 4 | C41: Besi ø8 | D41: =IFERROR(HLOOKUP($J$1,[1]DB!$C$1:$K$172,41,FALSE),"") -> 9 | E41: =SUMIFS('[1]Rincian Keluar'!$G:$G,'[1]Rincian Keluar'!$E:$E,'PELANGI 04'!C41,'[1]Rincian Keluar'!$D:$D,'PELANGI 04'!$D$1,'[1]Rincian Keluar'!$H:$H,'PELANGI 04'!$J$1,'[1]Rincian Keluar'!$F:$F,'PELANGI 04'!M41) -> 0 | F41: 35000 | G41: =E41*F41 -> 0 | M41: =$C$37 -> BATA
B42: 5 | C42: Besi ø6 | D42: =IFERROR(HLOOKUP($J$1,[1]DB!$C$1:$K$172,42,FALSE),"") -> 2 | E42: =SUMIFS('[1]Rincian Keluar'!$G:$G,'[1]Rincian Keluar'!$E:$E,'PELANGI 04'!C42,'[1]Rincian Keluar'!$D:$D,'PELANGI 04'!$D$1,'[1]Rincian Keluar'!$H:$H,'PELANGI 04'!$J$1,'[1]Rincian Keluar'!$F:$F,'PELANGI 04'!M42) -> 0 | F42: =F40 -> 22000 | G42: =E42*F42 -> 0 | M42: =$C$37 -> BATA
...

Sheet ILALANG 02
B1: LOKASI | D1: ILALANG 02 | H1: TYPE | J1: 60
B4: No. | C4: URAIAN PEKERJAAN | D4: BAHAN | F4: HARGA BAHAN | G4: TOTAL HARGA | H4: UPAH | I4: BORONGAN | J4: UNTUNG/RUGI | K4: PROGRES
D5: BAKU | E5: OUT | F5: ( Rp ) | G5: ( Rp )
B6: A | C6: PONDASI
B7: 1 | C7: Besi ø6 | D7: =IFERROR(HLOOKUP($J$1,[1]DB!$C$1:$K$172,7,FALSE),"") -> 15 | E7: =SUMIFS('[1]Rincian Keluar'!$G:$G,'[1]Rincian Keluar'!$E:$E,'ILALANG 02'!C7,'[1]Rincian Keluar'!$D:$D,'ILALANG 02'!$D$1,'[1]Rincian Keluar'!$H:$H,'ILALANG 02'!$J$1,'[1]Rincian Keluar'!$F:$F,'ILALANG 02'!M7) -> 0 | F7: 21500 | G7: =E7*F7 -> 0 | H7: 2304000 | I7: =IFERROR(VLOOKUP($C6,[1]HK!$B$5:$C$14,2,FALSE),"")*$J1 -> 2502000 | J7: =I7-H7 -> 198000 | K7: 1 | M7: =$C$6 -> PONDASI
B8: 2 | C8: Besi ø8 Ulir | D8: =IFERROR(HLOOKUP($J$1,[1]DB!$C$1:$K$172,8,FALSE),"") -> 50 | E8: =SUMIFS('[1]Rincian Keluar'!$G:$G,'[1]Rincian Keluar'!$E:$E,'ILALANG 02'!C8,'[1]Rincian Keluar'!$D:$D,'ILALANG 02'!$D$1,'[1]Rincian Keluar'!$H:$H,'ILALANG 02'!$J$1,'[1]Rincian Keluar'!$F:$F,'ILALANG 02'!M8) -> 15 | F8: 49000 | G8: =E8*F8 -> 735000 | M8: =$C$6 -> PONDASI
B9: 3 | C9: Kayu 3/5 | D9: =IFERROR(HLOOKUP($J$1,[1]DB!$C$1:$K$172,9,FALSE),"") -> 42 | E9: =SUMIFS('[1]Rincian Keluar'!$G:$G,'[1]Rincian Keluar'!$E:$E,'ILALANG 02'!C9,'[1]Rincian Keluar'!$D:$D,'ILALANG 02'!$D$1,'[1]Rincian Keluar'!$H:$H,'ILALANG 02'!$J$1,'[1]Rincian Keluar'!$F:$F,'ILALANG 02'!M9) -> 15 | F9: 11000 | G9: =E9*F9 -> 165000 | M9: =$C$6 -> PONDASI
B10: 4 | C10: Cerucuk | D10: =IFERROR(HLOOKUP($J$1,[1]DB!$C$1:$K$172,10,FALSE),"") -> 89 | E10: =SUMIFS('[1]Rincian Keluar'!$G:$G,'[1]Rincian Keluar'!$E:$E,'ILALANG 02'!C10,'[1]Rincian Keluar'!$D:$D,'ILALANG 02'!$D$1,'[1]Rincian Keluar'!$H:$H,'ILALANG 02'!$J$1,'[1]Rincian Keluar'!$F:$F,'ILALANG 02'!M10) -> 98 | F10: 8000 | G10: =E10*F10 -> 784000 | M10: =$C$6 -> PONDASI
B11: 5 | C11: Papan Mal | D11: =IFERROR(HLOOKUP($J$1,[1]DB!$C$1:$K$172,11,FALSE),"") -> 197 | E11: =SUMIFS('[1]Rincian Keluar'!$G:$G,'[1]Rincian Keluar'!$E:$E,'ILALANG 02'!C11,'[1]Rincian Keluar'!$D:$D,'ILALANG 02'!$D$1,'[1]Rincian Keluar'!$H:$H,'ILALANG 02'!$J$1,'[1]Rincian Keluar'!$F:$F,'ILALANG 02'!M11) -> 197 | F11: 11000 | G11: =E11*F11 -> 2167000 | M11: =$C$6 -> PONDASI
B12: 6 | C12: Pasir | D12: =IFERROR(HLOOKUP($J$1,[1]DB!$C$1:$K$172,12,FALSE),"") -> 16 | E12: =SUMIFS('[1]Rincian Keluar'!$G:$G,'[1]Rincian Keluar'!$E:$E,'ILALANG 02'!C12,'[1]Rincian Keluar'!$D:$D,'ILALANG 02'!$D$1,'[1]Rincian Keluar'!$H:$H,'ILALANG 02'!$J$1,'[1]Rincian Keluar'!$F:$F,'ILALANG 02'!M12) -> 15 | F12: 150000 | G12: =E12*F12 -> 2250000 | M12: =$C$6 -> PONDASI
B13: 7 | C13: Batu | D13: =IFERROR(HLOOKUP($J$1,[1]DB!$C$1:$K$172,13,FALSE),"") -> 3 | E13: =SUMIFS('[1]Rincian Keluar'!$G:$G,'[1]Rincian Keluar'!$E:$E,'ILALANG 02'!C13,'[1]Rincian Keluar'!$D:$D,'ILALANG 02'!$D$1,'[1]Rincian Keluar'!$H:$H,'ILALANG 02'!$J$1,'[1]Rincian Keluar'!$F:$F,'ILALANG 02'!M13) -> 1 | F13: 500000 | G13: =E13*F13 -> 500000 | M13: =$C$6 -> PONDASI
B14: 8 | C14: Semen PCC 40 Kg Tiga Roda | D14: =IFERROR(HLOOKUP($J$1,[1]DB!$C$1:$K$172,14,FALSE),"") -> 46 | E14: =SUMIFS('[1]Rincian Keluar'!$G:$G,'[1]Rincian Keluar'!$E:$E,'ILALANG 02'!C14,'[1]Rincian Keluar'!$D:$D,'ILALANG 02'!$D$1,'[1]Rincian Keluar'!$H:$H,'ILALANG 02'!$J$1,'[1]Rincian Keluar'!$F:$F,'ILALANG 02'!M14) -> 44 | F14: 60700 | G14: =E14*F14 -> 2670800 | M14: =$C$6 -> PONDASI
B15: B | C15: URUG
B16: 1 | C16: Pasir | D16: =IFERROR(HLOOKUP($J$1,[1]DB!$C$1:$K$172,16,FALSE),"") -> 39 | E16: =SUMIFS('[1]Rincian Keluar'!$G:$G,'[1]Rincian Keluar'!$E:$E,'ILALANG 02'!C16,'[1]Rincian Keluar'!$D:$D,'ILALANG 02'!$D$1,'[1]Rincian Keluar'!$H:$H,'ILALANG 02'!$J$1,'[1]Rincian Keluar'!$F:$F,'ILALANG 02'!M16) -> 37 | F16: 150000 | G16: =E16*F16 -> 5550000 | H16: 976500 | I16: =IFERROR(VLOOKUP($C15,[1]HK!$B$5:$C$14,2,FALSE),"")*$J1 -> 1002000 | J16: =I16-H16 -> 25500 | K16: 1 | M16: =$C$15 -> URUG
B17: 2 | C17: Pipa 4" | D17: =IFERROR(HLOOKUP($J$1,[1]DB!$C$1:$K$172,17,FALSE),"") -> 2 | E17: =SUMIFS('[1]Rincian Keluar'!$G:$G,'[1]Rincian Keluar'!$E:$E,'ILALANG 02'!C17,'[1]Rincian Keluar'!$D:$D,'ILALANG 02'!$D$1,'[1]Rincian Keluar'!$H:$H,'ILALANG 02'!$J$1,'[1]Rincian Keluar'!$F:$F,'ILALANG 02'!M17) -> 2 | F17: 133500 | G17: =E17*F17 -> 267000 | M17: =$C$15 -> URUG
B18: 3 | C18: Pipa 2" | D18: =IFERROR(HLOOKUP($J$1,[1]DB!$C$1:$K$172,18,FALSE),"") -> 2 | E18: =SUMIFS('[1]Rincian Keluar'!$G:$G,'[1]Rincian Keluar'!$E:$E,'ILALANG 02'!C18,'[1]Rincian Keluar'!$D:$D,'ILALANG 02'!$D$1,'[1]Rincian Keluar'!$H:$H,'ILALANG 02'!$J$1,'[1]Rincian Keluar'!$F:$F,'ILALANG 02'!M18) -> 2 | F18: 48000 | G18: =E18*F18 -> 96000 | M18: =$C$15 -> URUG
B19: C | C19: COR LANTAI
B20: 1 | C20: Besi ø6 | D20: =IFERROR(HLOOKUP($J$1,[1]DB!$C$1:$K$172,20,FALSE),"") -> 19 | E20: =SUMIFS('[1]Rincian Keluar'!$G:$G,'[1]Rincian Keluar'!$E:$E,'ILALANG 02'!C20,'[1]Rincian Keluar'!$D:$D,'ILALANG 02'!$D$1,'[1]Rincian Keluar'!$H:$H,'ILALANG 02'!$J$1,'[1]Rincian Keluar'!$F:$F,'ILALANG 02'!M20) -> 15 | F20: 22000 | G20: =E20*F20 -> 330000 | H20: 504000 | I20: =IFERROR(VLOOKUP($C19,[1]HK!$B$5:$C$14,2,FALSE),"")*$J1 -> 600000 | J20: =I20-H20 -> 96000 | K20: 1 | M20: =$C$19 -> COR LANTAI
B21: 2 | C21: Pasir | D21: =IFERROR(HLOOKUP($J$1,[1]DB!$C$1:$K$172,21,FALSE),"") -> 6 | E21: =SUMIFS('[1]Rincian Keluar'!$G:$G,'[1]Rincian Keluar'!$E:$E,'ILALANG 02'!C21,'[1]Rincian Keluar'!$D:$D,'ILALANG 02'!$D$1,'[1]Rincian Keluar'!$H:$H,'ILALANG 02'!$J$1,'[1]Rincian Keluar'!$F:$F,'ILALANG 02'!M21) -> 2 | F21: 150000 | G21: =E21*F21 -> 300000 | M21: =$C$19 -> COR LANTAI
B22: 3 | C22: Semen PCC 40 Kg Tiga Roda | D22: =IFERROR(HLOOKUP($J$1,[1]DB!$C$1:$K$172,22,FALSE),"") -> 17 | E22: =SUMIFS('[1]Rincian Keluar'!$G:$G,'[1]Rincian Keluar'!$E:$E,'ILALANG 02'!C22,'[1]Rincian Keluar'!$D:$D,'ILALANG 02'!$D$1,'[1]Rincian Keluar'!$H:$H,'ILALANG 02'!$J$1,'[1]Rincian Keluar'!$F:$F,'ILALANG 02'!M22) -> 11 | F22: 60700 | G22: =E22*F22 -> 667700 | M22: =$C$19 -> COR LANTAI
B23: 4 | C23: Plastik cor | D23: =IFERROR(HLOOKUP($J$1,[1]DB!$C$1:$K$172,23,FALSE),"") -> 8 | E23: =SUMIFS('[1]Rincian Keluar'!$G:$G,'[1]Rincian Keluar'!$E:$E,'ILALANG 02'!C23,'[1]Rincian Keluar'!$D:$D,'ILALANG 02'!$D$1,'[1]Rincian Keluar'!$H:$H,'ILALANG 02'!$J$1,'[1]Rincian Keluar'!$F:$F,'ILALANG 02'!M23) -> 7 | F23: 15000 | G23: =E23*F23 -> 105000 | M23: =$C$19 -> COR LANTAI
B24: D | C24: PINTU
B25: 1 | C25: Pintu Kayu 120 x 220 | D25: =IFERROR(HLOOKUP($J$1,[1]DB!$C$1:$K$172,25,FALSE),"") -> 1 | E25: =SUMIFS('[1]Rincian Keluar'!$G:$G,'[1]Rincian Keluar'!$E:$E,'ILALANG 02'!C25,'[1]Rincian Keluar'!$D:$D,'ILALANG 02'!$D$1,'[1]Rincian Keluar'!$H:$H,'ILALANG 02'!$J$1,'[1]Rincian Keluar'!$F:$F,'ILALANG 02'!M25) -> 0 | F25: 1550000 | G25: =E25*F25 -> 0 | I25: =IFERROR(VLOOKUP($C24,[1]HK!$B$5:$C$14,2,FALSE),"")*$J1 -> #VALUE! | M25: =$C$24 -> PINTU
B26: 2 | C26: Pintu Kayu 80 x 220 | D26: =IFERROR(HLOOKUP($J$1,[1]DB!$C$1:$K$172,26,FALSE),"") -> 3 | E26: =SUMIFS('[1]Rincian Keluar'!$G:$G,'[1]Rincian Keluar'!$E:$E,'ILALANG 02'!C26,'[1]Rincian Keluar'!$D:$D,'ILALANG 02'!$D$1,'[1]Rincian Keluar'!$H:$H,'ILALANG 02'!$J$1,'[1]Rincian Keluar'!$F:$F,'ILALANG 02'!M26) -> 0 | F26: 775000 | G26: =E26*F26 -> 0 | M26: =$C$24 -> PINTU
B27: 3 | C27: Pintu WC PVC Biru | D27: =IFERROR(HLOOKUP($J$1,[1]DB!$C$1:$K$172,27,FALSE),"") -> 2 | E27: =SUMIFS('[1]Rincian Keluar'!$G:$G,'[1]Rincian Keluar'!$E:$E,'ILALANG 02'!C27,'[1]Rincian Keluar'!$D:$D,'ILALANG 02'!$D$1,'[1]Rincian Keluar'!$H:$H,'ILALANG 02'!$J$1,'[1]Rincian Keluar'!$F:$F,'ILALANG 02'!M27) -> 0 | F27: 260000 | G27: =E27*F27 -> 0 | M27: =$C$24 -> PINTU
B28: 4 | C28: Pintu WC Edenjoice Putih | D28: =IFERROR(HLOOKUP($J$1,[1]DB!$C$1:$K$172,28,FALSE),"") -> 1 | E28: =SUMIFS('[1]Rincian Keluar'!$G:$G,'[1]Rincian Keluar'!$E:$E,'ILALANG 02'!C28,'[1]Rincian Keluar'!$D:$D,'ILALANG 02'!$D$1,'[1]Rincian Keluar'!$H:$H,'ILALANG 02'!$J$1,'[1]Rincian Keluar'!$F:$F,'ILALANG 02'!M28) -> 0 | F28: 799000 | G28: =E28*F28 -> 0 | M28: =$C$24 -> PINTU
